Workbook

Sheet BACKUP COUNTS
A1: Date | B1: Route | C1: Block | D1: Time | E1: Count | F1: Increment | G1: Hour | H1: Minute | I1: Error?
F2: =IF($A2="","",$E2) | G2: =IF($A2="","",HOUR($D2)) | H2: =IF($A2="","",MINUTE($D2))
F3: =IF($A3="","",$E3-_xlfn.MAXIFS($E2:$E$2,$C2:$C$2,$C3,$A2:$A$2,$A3)) | G3: =IF($A3="","",HOUR($D3)) | H3: =IF($A3="","",MINUTE($D3)) | I3: =IF($F3<0,"ERROR","")
F4: =IF($A4="","",$E4-_xlfn.MAXIFS($E$2:$E3,$C$2:$C3,$C4,$A$2:$A3,$A4)) | G4: =IF($A4="","",HOUR($D4)) | H4: =IF($A4="","",MINUTE($D4)) | I4: =IF($F4<0,"ERROR","")
F5: =IF($A5="","",$E5-_xlfn.MAXIFS($E$2:$E4,$C$2:$C4,$C5,$A$2:$A4,$A5)) | G5: =IF($A5="","",HOUR($D5)) | H5: =IF($A5="","",MINUTE($D5)) | I5: =IF($F5<0,"ERROR","")
F6: =IF($A6="","",$E6-_xlfn.MAXIFS($E$2:$E5,$C$2:$C5,$C6,$A$2:$A5,$A6)) | G6: =IF($A6="","",HOUR($D6)) | H6: =IF($A6="","",MINUTE($D6)) | I6: =IF($F6<0,"ERROR","")
F7: =IF($A7="","",$E7-_xlfn.MAXIFS($E$2:$E6,$C$2:$C6,$C7,$A$2:$A6,$A7)) | G7: =IF($A7="","",HOUR($D7)) | H7: =IF($A7="","",MINUTE($D7)) | I7: =IF($F7<0,"ERROR","")
F8: =IF($A8="","",$E8-_xlfn.MAXIFS($E$2:$E7,$C$2:$C7,$C8,$A$2:$A7,$A8)) | G8: =IF($A8="","",HOUR($D8)) | H8: =IF($A8="","",MINUTE($D8)) | I8: =IF($F8<0,"ERROR","")
F9: =IF($A9="","",$E9-_xlfn.MAXIFS($E$2:$E8,$C$2:$C8,$C9,$A$2:$A8,$A9)) | G9: =IF($A9="","",HOUR($D9)) | H9: =IF($A9="","",MINUTE($D9)) | I9: =IF($F9<0,"ERROR","")
F10: =IF($A10="","",$E10-_xlfn.MAXIFS($E$2:$E9,$C$2:$C9,$C10,$A$2:$A9,$A10)) | G10: =IF($A10="","",HOUR($D10)) | H10: =IF($A10="","",MINUTE($D10)) | I10: =IF($F10<0,"ERROR","")
F11: =IF($A11="","",$E11-_xlfn.MAXIFS($E$2:$E10,$C$2:$C10,$C11,$A$2:$A10,$A11)) | G11: =IF($A11="","",HOUR($D11)) | H11: =IF($A11="","",MINUTE($D11)) | I11: =IF($F11<0,"ERROR","")
F12: =IF($A12="","",$E12-_xlfn.MAXIFS($E$2:$E11,$C$2:$C11,$C12,$A$2:$A11,$A12)) | G12: =IF($A12="","",HOUR($D12)) | H12: =IF($A12="","",MINUTE($D12)) | I12: =IF($F12<0,"ERROR","")
F13: =IF($A13="","",$E13-_xlfn.MAXIFS($E$2:$E12,$C$2:$C12,$C13,$A$2:$A12,$A13)) | G13: =IF($A13="","",HOUR($D13)) | H13: =IF($A13="","",MINUTE($D13)) | I13: =IF($F13<0,"ERROR","")
F14: =IF($A14="","",$E14-_xlfn.MAXIFS($E$2:$E13,$C$2:$C13,$C14,$A$2:$A13,$A14)) | G14: =IF($A14="","",HOUR($D14)) | H14: =IF($A14="","",MINUTE($D14)) | I14: =IF($F14<0,"ERROR","")
F15: =IF($A15="","",$E15-_xlfn.MAXIFS($E$2:$E14,$C$2:$C14,$C15,$A$2:$A14,$A15)) | G15: =IF($A15="","",HOUR($D15)) | H15: =IF($A15="","",MINUTE($D15)) | I15: =IF($F15<0,"ERROR","")
... F377: =IF($A377="","",$E377-_xlfn.MAXIFS($E$2:$E376,$C$2:$C376,$C377,$A$2:$A376,$A377)) | G377: =IF($A377="","",HOUR($D377)) | H377: =IF($A377="","",MINUTE($D377)) | I377: =IF($F377<0,"ERROR","")
F378: 18 | G378: =IF($A378="","",HOUR($D378)) | H378: =IF($A378="","",MINUTE($D378)) | I378: =IF($F378<0,"ERROR","")
F379: =IF($A379="","",$E379-_xlfn.MAXIFS($E$2:$E378,$C$2:$C378,$C379,$A$2:$A378,$A379)) | G379: =IF($A379="","",HOUR($D379)) | H379: =IF($A379="","",MINUTE($D379)) | I379: =IF($F379<0,"ERROR","")
F380: =IF($A380="","",$E380-_xlfn.MAXIFS($E$2:$E379,$C$2:$C379,$C380,$A$2:$A379,$A380)) | G380: =IF($A380="","",HOUR($D380)) | H380: =IF($A380="","",MINUTE($D380)) | I380: =IF($F380<0,"ERROR","")
F381: =IF($A381="","",$E381-_xlfn.MAXIFS($E$2:$E380,$C$2:$C380,$C381,$A$2:$A380,$A381)) | G381: =IF($A381="","",HOUR($D381)) | H381: =IF($A381="","",MINUTE($D381)) | I381: =IF($F381<0,"ERROR","")
F382: =IF($A382="","",$E382-_xlfn.MAXIFS($E$2:$E381,$C$2:$C381,$C382,$A$2:$A381,$A382)) | G382: =IF($A382="","",HOUR($D382)) | H382: =IF($A382="","",MINUTE($D382)) | I382: =IF($F382<0,"ERROR","")
F383: =IF($A383="","",$E383-_xlfn.MAXIFS($E$2:$E382,$C$2:$C382,$C383,$A$2:$A382,$A383)) | G383: =IF($A383="","",HOUR($D383)) | H383: =IF($A383="","",MINUTE($D383)) | I383: =IF($F383<0,"ERROR","")
F384: =IF($A384="","",$E384-_xlfn.MAXIFS($E$2:$E383,$C$2:$C383,$C384,$A$2:$A383,$A384)) | G384: =IF($A384="","",HOUR($D384)) | H384: =IF($A384="","",MINUTE($D384)) | I384: =IF($F384<0,"ERROR","")
F385: =IF($A385="","",$E385-_xlfn.MAXIFS($E$2:$E384,$C$2:$C384,$C385,$A$2:$A384,$A385)) | G385: =IF($A385="","",HOUR($D385)) | H385: =IF($A385="","",MINUTE($D385)) | I385: =IF($F385<0,"ERROR","")
F386: =IF($A386="","",$E386-_xlfn.MAXIFS($E$2:$E385,$C$2:$C385,$C386,$A$2:$A385,$A386)) | G386: =IF($A386="","",HOUR($D386)) | H386: =IF($A386="","",MINUTE($D386)) | I386: =IF($F386<0,"ERROR","")
F387: =IF($A387="","",$E387-_xlfn.MAXIFS($E$2:$E386,$C$2:$C386,$C387,$A$2:$A386,$A387)) | G387: =IF($A387="","",HOUR($D387)) | H387: =IF($A387="","",MINUTE($D387)) | I387: =IF($F387<0,"ERROR","")
F388: =IF($A388="","",$E388-_xlfn.MAXIFS($E$2:$E387,$C$2:$C387,$C388,$A$2:$A387,$A388)) | G388: =IF($A388="","",HOUR($D388)) | H388: =IF($A388="","",MINUTE($D388)) | I388: =IF($F388<0,"ERROR","")
F389: =IF($A389="","",$E389-_xlfn.MAXIFS($E$2:$E388,$C$2:$C388,$C389,$A$2:$A388,$A389)) | G389: =IF($A389="","",HOUR($D389)) | H389: =IF($A389="","",MINUTE($D389)) | I389: =IF($F389<0,"ERROR","")
F390: =IF($A390="","",$E390-_xlfn.MAXIFS($E$2:$E389,$C$2:$C389,$C390,$A$2:$A389,$A390)) | G390: =IF($A390="","",HOUR($D390)) | H390: =IF($A390="","",MINUTE($D390)) | I390: =IF($F390<0,"ERROR","")
... F9941: =IF($A9941="","",$E9941-_xlfn.MAXIFS($E$2:$E9940,$C$2:$C9940,$C9941,$A$2:$A9940,$A9941)) | G9941: =IF($A9941="","",HOUR($D9941)) | H9941: =IF($A9941="","",MINUTE($D9941)) | I9941: =IF($F9941<0,"ERROR","")

Sheet BACKUP CALCULATIONS
A1: =TODAY() -> 46146 | B1: TOTAL | C1: 500 | D1: 530 | E1: 600 | F1: 630 | G1: 700 | H1: 730 | I1: 800 | J1: 830 | K1: 900 | L1: 930 | M1: 1000 | N1: 1030 | O1: 1100 | P1: 1130 | Q1: 1200 | R1: 1230 | S1: 1300 | T1: 1330 | U1: 1400 | V1: 1430 | W1: 1500 | X1: 1530 | Y1: 1600 | Z1: 1630 | AA1: 1700 | AB1: 1730 | AC1: 1800 | AD1: 1830 | AE1: 1900 | AF1: 1930
C2: 5 | D2: 5 | E2: 6 | F2: 6 | G2: 7 | H2: 7 | I2: 8 | J2: 8 | K2: 9 | L2: 9 | M2: 10 | N2: 10 | O2: 11 | P2: 11 | Q2: 12 | R2: 12 | S2: 13 | T2: 13 | U2: 14 | V2: 14 | W2: 15 | X2: 15 | Y2: 16 | Z2: 16 | AA2: 17 | AB2: 17 | AC2: 18 | AD2: 18 | AE2: 19 | AF2: 19
A3: PURPLE | B3: =SUMIFS('BACKUP COUNTS'!$F:$F,'BACKUP COUNTS'!$B:$B,$A3,'BACKUP COUNTS'!$A:$A,$A$1) -> 0 | C3: =SUMIFS('BACKUP COUNTS'!$F:$F,'BACKUP COUNTS'!$B:$B,$A3,'BACKUP COUNTS'!$G:$G,C$2,'BACKUP COUNTS'!$H:$H,"<30",'BACKUP COUNTS'!$A:$A,$A$1) -> 0 | D3: =SUMIFS('BACKUP COUNTS'!$F:$F,'BACKUP COUNTS'!$B:$B,$A3,'BACKUP COUNTS'!$G:$G,D$2,'BACKUP COUNTS'!$H:$H,">=30",'BACKUP COUNTS'!$A:$A,$A$1) -> 0 | E3: =SUMIFS('BACKUP COUNTS'!$F:$F,'BACKUP COUNTS'!$B:$B,$A3,'BACKUP COUNTS'!$G:$G,E$2,'BACKUP COUNTS'!$H:$H,"<30",'BACKUP COUNTS'!$A:$A,$A$1) -> 0 | F3: =SUMIFS('BACKUP COUNTS'!$F:$F,'BACKUP COUNTS'!$B:$B,$A3,'BACKUP COUNTS'!$G:$G,F$2,'BACKUP COUNTS'!$H:$H,">=30",'BACKUP COUNTS'!$A:$A,$A$1) -> 0 | G3: =SUMIFS('BACKUP COUNTS'!$F:$F,'BACKUP COUNTS'!$B:$B,$A3,'BACKUP COUNTS'!$G:$G,G$2,'BACKUP COUNTS'!$H:$H,"<30",'BACKUP COUNTS'!$A:$A,$A$1) -> 0 | H3: =SUMIFS('BACKUP COUNTS'!$F:$F,'BACKUP COUNTS'!$B:$B,$A3,'BACKUP COUNTS'!$G:$G,H$2,'BACKUP COUNTS'!$H:$H,">=30",'BACKUP COUNTS'!$A:$A,$A$1) -> 0 | I3: =SUMIFS('BACKUP COUNTS'!$F:$F,'BACKUP COUNTS'!$B:$B,$A3,'BACKUP COUNTS'!$G:$G,I$2,'BACKUP COUNTS'!$H:$H,"<30",'BACKUP COUNTS'!$A:$A,$A$1) -> 0 | J3: =SUMIFS('BACKUP COUNTS'!$F:$F,'BACKUP COUNTS'!$B:$B,$A3,'BACKUP COUNTS'!$G:$G,J$2,'BACKUP COUNTS'!$H:$H,">=30",'BACKUP COUNTS'!$A:$A,$A$1) -> 0 | K3: =SUMIFS('BACKUP COUNTS'!$F:$F,'BACKUP COUNTS'!$B:$B,$A3,'BACKUP COUNTS'!$G:$G,K$2,'BACKUP COUNTS'!$H:$H,"<30",'BACKUP COUNTS'!$A:$A,$A$1) -> 0 | L3: =SUMIFS('BACKUP COUNTS'!$F:$F,'BACKUP COUNTS'!$B:$B,$A3,'BACKUP COUNTS'!$G:$G,L$2,'BACKUP COUNTS'!$H:$H,">=30",'BACKUP COUNTS'!$A:$A,$A$1) -> 0 | M3: =SUMIFS('BACKUP COUNTS'!$F:$F,'BACKUP COUNTS'!$B:$B,$A3,'BACKUP COUNTS'!$G:$G,M$2,'BACKUP COUNTS'!$H:$H,"<30",'BACKUP COUNTS'!$A:$A,$A$1) -> 0 | N3: =SUMIFS('BACKUP COUNTS'!$F:$F,'BACKUP COUNTS'!$B:$B,$A3,'BACKUP COUNTS'!$G:$G,N$2,'BACKUP COUNTS'!$H:$H,">=30",'BACKUP COUNTS'!$A:$A,$A$1) -> 0 | O3: =SUMIFS('BACKUP COUNTS'!$F:$F,'BACKUP COUNTS'!$B:$B,$A3,'BACKUP COUNTS'!$G:$G,O$2,'BACKUP COUNTS'!$H:$H,"<30",'BACKUP COUNTS'!$A:$A,$A$1) -> 0 | P3: =SUMIFS('BACKUP COUNTS'!$F:$F,'BACKUP COUNTS'!$B:$B,$A3,'BACKUP COUNTS'!$G:$G,P$2,'BACKUP COUNTS'!$H:$H,">=30",'BACKUP COUNTS'!$A:$A,$A$1) -> 0 | Q3: =SUMIFS('BACKUP COUNTS'!$F:$F,'BACKUP COUNTS'!$B:$B,$A3,'BACKUP COUNTS'!$G:$G,Q$2,'BACKUP COUNTS'!$H:$H,"<30",'BACKUP COUNTS'!$A:$A,$A$1) -> 0 | R3: =SUMIFS('BACKUP COUNTS'!$F:$F,'BACKUP COUNTS'!$B:$B,$A3,'BACKUP COUNTS'!$G:$G,R$2,'BACKUP COUNTS'!$H:$H,">=30",'BACKUP COUNTS'!$A:$A,$A$1) -> 0 | S3: =SUMIFS('BACKUP COUNTS'!$F:$F,'BACKUP COUNTS'!$B:$B,$A3,'BACKUP COUNTS'!$G:$G,S$2,'BACKUP COUNTS'!$H:$H,"<30",'BACKUP COUNTS'!$A:$A,$A$1) -> 0 | T3: =SUMIFS('BACKUP COUNTS'!$F:$F,'BACKUP COUNTS'!$B:$B,$A3,'BACKUP COUNTS'!$G:$G,T$2,'BACKUP COUNTS'!$H:$H,">=30",'BACKUP COUNTS'!$A:$A,$A$1) -> 0 | U3: =SUMIFS('BACKUP COUNTS'!$F:$F,'BACKUP COUNTS'!$B:$B,$A3,'BACKUP COUNTS'!$G:$G,U$2,'BACKUP COUNTS'!$H:$H,"<30",'BACKUP COUNTS'!$A:$A,$A$1) -> 0 | V3: =SUMIFS('BACKUP COUNTS'!$F:$F,'BACKUP COUNTS'!$B:$B,$A3,'BACKUP COUNTS'!$G:$G,V$2,'BACKUP COUNTS'!$H:$H,">=30",'BACKUP COUNTS'!$A:$A,$A$1) -> 0 | W3: =SUMIFS('BACKUP COUNTS'!$F:$F,'BACKUP COUNTS'!$B:$B,$A3,'BACKUP COUNTS'!$G:$G,W$2,'BACKUP COUNTS'!$H:$H,"<30",'BACKUP COUNTS'!$A:$A,$A$1) -> 0 | X3: =SUMIFS('BACKUP COUNTS'!$F:$F,'BACKUP COUNTS'!$B:$B,$A3,'BACKUP COUNTS'!$G:$G,X$2,'BACKUP COUNTS'!$H:$H,">=30",'BACKUP COUNTS'!$A:$A,$A$1) -> 0 | Y3: =SUMIFS('BACKUP COUNTS'!$F:$F,'BACKUP COUNTS'!$B:$B,$A3,'BACKUP COUNTS'!$G:$G,Y$2,'BACKUP COUNTS'!$H:$H,"<30",'BACKUP COUNTS'!$A:$A,$A$1) -> 0 | Z3: =SUMIFS('BACKUP COUNTS'!$F:$F,'BACKUP COUNTS'!$B:$B,$A3,'BACKUP COUNTS'!$G:$G,Z$2,'BACKUP COUNTS'!$H:$H,">=30",'BACKUP COUNTS'!$A:$A,$A$1) -> 0 | AA3: =SUMIFS('BACKUP COUNTS'!$F:$F,'BACKUP COUNTS'!$B:$B,$A3,'BACKUP COUNTS'!$G:$G,AA$2,'BACKUP COUNTS'!$H:$H,"<30",'BACKUP COUNTS'!$A:$A,$A$1) -> 0 | AB3: =SUMIFS('BACKUP COUNTS'!$F:$F,'BACKUP COUNTS'!$B:$B,$A3,'BACKUP COUNTS'!$G:$G,AB$2,'BACKUP COUNTS'!$H:$H,">=30",'BACKUP COUNTS'!$A:$A,$A$1) -> 0 | AC3: =SUMIFS('BACKUP COUNTS'!$F:$F,'BACKUP COUNTS'!$B:$B,$A3,'BACKUP COUNTS'!$G:$G,AC$2,'BACKUP COUNTS'!$H:$H,"<30",'BACKUP COUNTS'!$A:$A,$A$1) -> 0 | AD3: =SUMIFS('BACKUP COUNTS'!$F:$F,'BACKUP COUNTS'!$B:$B,$A3,'BACKUP COUNTS'!$G:$G,AD$2,'BACKUP COUNTS'!$H:$H,">=30",'BACKUP COUNTS'!$A:$A,$A$1) -> 0 | AE3: =SUMIFS('BACKUP COUNTS'!$F:$F,'BACKUP COUNTS'!$B:$B,$A3,'BACKUP COUNTS'!$G:$G,AE$2,'BACKUP COUNTS'!$H:$H,"<30",'BACKUP COUNTS'!$A:$A,$A$1) -> 0 | AF3: =SUMIFS('BACKUP COUNTS'!$F:$F,'BACKUP COUNTS'!$B:$B,$A3,'BACKUP COUNTS'!$G:$G,AF$2,'BACKUP COUNTS'!$H:$H,">=30",'BACKUP COUNTS'!$A:$A,$A$1) -> 0
C5: 5 | D5: 6 | E5: 7 | F5: 8 | G5: 9 | H5: 10 | I5: 11 | J5: 12 | K5: 13 | L5: 14 | M5: 15 | N5: 16 | O5: 17 | P5: 18 | Q5: 19
B6: PURPLE | C6: {=IFERROR(_xlfn.XLOOKUP($A$1,'BACKUP BY DAY'!$A$4:$A$264,_xlfn.XLOOKUP(C$5,'BACKUP BY DAY'!$D$2:$K$2,'BACKUP BY DAY'!$D$4:$K$264)),"")} | D6: {=IFERROR(_xlfn.XLOOKUP($A$1,'BACKUP BY DAY'!$A$4:$A$264,_xlfn.XLOOKUP(D$5,'BACKUP BY DAY'!$D$2:$K$2,'BACKUP BY DAY'!$D$4:$K$264)),"")} | E6: {=IFERROR(_xlfn.XLOOKUP($A$1,'BACKUP BY DAY'!$A$4:$A$264,_xlfn.XLOOKUP(E$5,'BACKUP BY DAY'!$D$2:$K$2,'BACKUP BY DAY'!$D$4:$K$264)),"")} | F6: {=IFERROR(_xlfn.XLOOKUP($A$1,'BACKUP BY DAY'!$A$4:$A$264,_xlfn.XLOOKUP(F$5,'BACKUP BY DAY'!$D$2:$K$2,'BACKUP BY DAY'!$D$4:$K$264)),"")} | G6: {=IFERROR(_xlfn.XLOOKUP($A$1,'BACKUP BY DAY'!$A$4:$A$264,_xlfn.XLOOKUP(G$5,'BACKUP BY DAY'!$D$2:$K$2,'BACKUP BY DAY'!$D$4:$K$264)),"")} | H6: {=IFERROR(_xlfn.XLOOKUP($A$1,'BACKUP BY DAY'!$A$4:$A$264,_xlfn.XLOOKUP(H$5,'BACKUP BY DAY'!$D$2:$K$2,'BACKUP BY DAY'!$D$4:$K$264)),"")} | I6: {=IFERROR(_xlfn.XLOOKUP($A$1,'BACKUP BY DAY'!$A$4:$A$264,_xlfn.XLOOKUP(I$5,'BACKUP BY DAY'!$D$2:$K$2,'BACKUP BY DAY'!$D$4:$K$264)),"")} | J6: {=IFERROR(_xlfn.XLOOKUP($A$1,'BACKUP BY DAY'!$A$4:$A$264,_xlfn.XLOOKUP(J$5,'BACKUP BY DAY'!$D$2:$K$2,'BACKUP BY DAY'!$D$4:$K$264)),"")} | ... Q6: {=IFERROR(_xlfn.XLOOKUP($A$1,'BACKUP BY DAY'!$A$4:$A$264,_xlfn.XLOOKUP(Q$5,'BACKUP BY DAY'!$D$2:$K$2,'BACKUP BY DAY'!$D$4:$K$264)),"")}
B7: PRP AVG | C7: =IFERROR(_xlfn.XLOOKUP(C$5,'BACKUP BY DAY'!$D$2:$K$2,'BACKUP BY DAY'!$D$3:$K$3),"") | D7: =IFERROR(_xlfn.XLOOKUP(D$5,'BACKUP BY DAY'!$D$2:$K$2,'BACKUP BY DAY'!$D$3:$K$3),"") | E7: =IFERROR(_xlfn.XLOOKUP(E$5,'BACKUP BY DAY'!$D$2:$K$2,'BACKUP BY DAY'!$D$3:$K$3),"") | F7: =IFERROR(_xlfn.XLOOKUP(F$5,'BACKUP BY DAY'!$D$2:$K$2,'BACKUP BY DAY'!$D$3:$K$3),"") | G7: =IFERROR(_xlfn.XLOOKUP(G$5,'BACKUP BY DAY'!$D$2:$K$2,'BACKUP BY DAY'!$D$3:$K$3),"") | H7: =IFERROR(_xlfn.XLOOKUP(H$5,'BACKUP BY DAY'!$D$2:$K$2,'BACKUP BY DAY'!$D$3:$K$3),"") | I7: =IFERROR(_xlfn.XLOOKUP(I$5,'BACKUP BY DAY'!$D$2:$K$2,'BACKUP BY DAY'!$D$3:$K$3),"") | J7: =IFERROR(_xlfn.XLOOKUP(J$5,'BACKUP BY DAY'!$D$2:$K$2,'BACKUP BY DAY'!$D$3:$K$3),"") | ... Q7: =IFERROR(_xlfn.XLOOKUP(Q$5,'BACKUP BY DAY'!$D$2:$K$2,'BACKUP BY DAY'!$D$3:$K$3),"")
C8: 0.20833333 | D8: 0.25 | E8: 0.29166667 | F8: 0.33333333 | G8: 0.375 | H8: 0.41666667 | I8: 0.45833333 | J8: 0.5 | K8: 0.54166667 | L8: 0.58333333 | M8: 0.625 | N8: 0.66666667 | O8: 0.70833333 | P8: 0.75 | Q8: 0.79166667

Sheet BACKUP BY DAY
D1: PURPLE | E1: PURPLE | F1: PURPLE | G1: PURPLE | H1: PURPLE | I1: PURPLE | J1: PURPLE | K1: PURPLE | L1: PURPLE | M1: PURPLE | N1: PURPLE | O1: PURPLE | P1: PURPLE | Q1: PURPLE | R1: PURPLE
C2: PURPLE | D2: 5 | E2: 6 | F2: 7 | G2: 8 | H2: 9 | I2: 10 | J2: 11 | K2: 12 | L2: 13 | M2: 14 | N2: 15 | O2: 16 | P2: 17 | Q2: 18 | R2: 19
A3: DATE | B3: TAGS | C3: =AVERAGEIFS(C$4:C$264,$B$4:$B$264,"Y") -> #DIV/0! | D3: =AVERAGEIFS(D$4:D$264,$B$4:$B$264,"Y") -> #DIV/0! | E3: =AVERAGEIFS(E$4:E$264,$B$4:$B$264,"Y") -> #DIV/0! | F3: =AVERAGEIFS(F$4:F$264,$B$4:$B$264,"Y") -> #DIV/0! | G3: =AVERAGEIFS(G$4:G$264,$B$4:$B$264,"Y") -> #DIV/0! | H3: =AVERAGEIFS(H$4:H$264,$B$4:$B$264,"Y") -> #DIV/0! | I3: =AVERAGEIFS(I$4:I$264,$B$4:$B$264,"Y") -> #DIV/0! | J3: =AVERAGEIFS(J$4:J$264,$B$4:$B$264,"Y") -> #DIV/0! | ... R3: =AVERAGEIFS(R$4:R$264,$B$4:$B$264,"Y") -> #DIV/0!
A4: 45839 | C4: =IF(SUMIFS('BACKUP COUNTS'!$F:$F,'BACKUP COUNTS'!$A:$A,$A4,'BACKUP COUNTS'!$B:$B,C$2)=0,"",SUMIFS('BACKUP COUNTS'!$F:$F,'BACKUP COUNTS'!$A:$A,$A4,'BACKUP COUNTS'!$B:$B,C$2)) | D4: =IF(SUMIFS('BACKUP COUNTS'!$F:$F,'BACKUP COUNTS'!$A:$A,$A4,'BACKUP COUNTS'!$B:$B,D$1,'BACKUP COUNTS'!$G:$G,D$2)=0,"",SUMIFS('BACKUP COUNTS'!$F:$F,'BACKUP COUNTS'!$A:$A,$A4,'BACKUP COUNTS'!$B:$B,D$1,'BACKUP COUNTS'!$G:$G,D$2)) | E4: =IF(SUMIFS('BACKUP COUNTS'!$F:$F,'BACKUP COUNTS'!$A:$A,$A4,'BACKUP COUNTS'!$B:$B,E$1,'BACKUP COUNTS'!$G:$G,E$2)=0,"",SUMIFS('BACKUP COUNTS'!$F:$F,'BACKUP COUNTS'!$A:$A,$A4,'BACKUP COUNTS'!$B:$B,E$1,'BACKUP COUNTS'!$G:$G,E$2)) | F4: =IF(SUMIFS('BACKUP COUNTS'!$F:$F,'BACKUP COUNTS'!$A:$A,$A4,'BACKUP COUNTS'!$B:$B,F$1,'BACKUP COUNTS'!$G:$G,F$2)=0,"",SUMIFS('BACKUP COUNTS'!$F:$F,'BACKUP COUNTS'!$A:$A,$A4,'BACKUP COUNTS'!$B:$B,F$1,'BACKUP COUNTS'!$G:$G,F$2)) | G4: =IF(SUMIFS('BACKUP COUNTS'!$F:$F,'BACKUP COUNTS'!$A:$A,$A4,'BACKUP COUNTS'!$B:$B,G$1,'BACKUP COUNTS'!$G:$G,G$2)=0,"",SUMIFS('BACKUP COUNTS'!$F:$F,'BACKUP COUNTS'!$A:$A,$A4,'BACKUP COUNTS'!$B:$B,G$1,'BACKUP COUNTS'!$G:$G,G$2)) | H4: =IF(SUMIFS('BACKUP COUNTS'!$F:$F,'BACKUP COUNTS'!$A:$A,$A4,'BACKUP COUNTS'!$B:$B,H$1,'BACKUP COUNTS'!$G:$G,H$2)=0,"",SUMIFS('BACKUP COUNTS'!$F:$F,'BACKUP COUNTS'!$A:$A,$A4,'BACKUP COUNTS'!$B:$B,H$1,'BACKUP COUNTS'!$G:$G,H$2)) | I4: =IF(SUMIFS('BACKUP COUNTS'!$F:$F,'BACKUP COUNTS'!$A:$A,$A4,'BACKUP COUNTS'!$B:$B,I$1,'BACKUP COUNTS'!$G:$G,I$2)=0,"",SUMIFS('BACKUP COUNTS'!$F:$F,'BACKUP COUNTS'!$A:$A,$A4,'BACKUP COUNTS'!$B:$B,I$1,'BACKUP COUNTS'!$G:$G,I$2)) | J4: =IF(SUMIFS('BACKUP COUNTS'!$F:$F,'BACKUP COUNTS'!$A:$A,$A4,'BACKUP COUNTS'!$B:$B,J$1,'BACKUP COUNTS'!$G:$G,J$2)=0,"",SUMIFS('BACKUP COUNTS'!$F:$F,'BACKUP COUNTS'!$A:$A,$A4,'BACKUP COUNTS'!$B:$B,J$1,'BACKUP COUNTS'!$G:$G,J$2)) | K4: =IF(SUMIFS('BACKUP COUNTS'!$F:$F,'BACKUP COUNTS'!$A:$A,$A4,'BACKUP COUNTS'!$B:$B,K$1,'BACKUP COUNTS'!$G:$G,K$2)=0,"",SUMIFS('BACKUP COUNTS'!$F:$F,'BACKUP COUNTS'!$A:$A,$A4,'BACKUP COUNTS'!$B:$B,K$1,'BACKUP COUNTS'!$G:$G,K$2)) | ... R4: =IF(SUMIFS('BACKUP COUNTS'!$F:$F,'BACKUP COUNTS'!$A:$A,$A4,'BACKUP COUNTS'!$B:$B,R$1,'BACKUP COUNTS'!$G:$G,R$2)=0,"",SUMIFS('BACKUP COUNTS'!$F:$F,'BACKUP COUNTS'!$A:$A,$A4,'BACKUP COUNTS'!$B:$B,R$1,'BACKUP COUNTS'!$G:$G,R$2))
A5: =IF(WEEKDAY(A4,2)=5,A4+3,A4+1) -> 45840 | C5: =IF(SUMIFS('BACKUP COUNTS'!$F:$F,'BACKUP COUNTS'!$A:$A,$A5,'BACKUP COUNTS'!$B:$B,C$2)=0,"",SUMIFS('BACKUP COUNTS'!$F:$F,'BACKUP COUNTS'!$A:$A,$A5,'BACKUP COUNTS'!$B:$B,C$2)) | D5: =IF(SUMIFS('BACKUP COUNTS'!$F:$F,'BACKUP COUNTS'!$A:$A,$A5,'BACKUP COUNTS'!$B:$B,D$1,'BACKUP COUNTS'!$G:$G,D$2)=0,"",SUMIFS('BACKUP COUNTS'!$F:$F,'BACKUP COUNTS'!$A:$A,$A5,'BACKUP COUNTS'!$B:$B,D$1,'BACKUP COUNTS'!$G:$G,D$2)) | E5: =IF(SUMIFS('BACKUP COUNTS'!$F:$F,'BACKUP COUNTS'!$A:$A,$A5,'BACKUP COUNTS'!$B:$B,E$1,'BACKUP COUNTS'!$G:$G,E$2)=0,"",SUMIFS('BACKUP COUNTS'!$F:$F,'BACKUP COUNTS'!$A:$A,$A5,'BACKUP COUNTS'!$B:$B,E$1,'BACKUP COUNTS'!$G:$G,E$2)) | F5: =IF(SUMIFS('BACKUP COUNTS'!$F:$F,'BACKUP COUNTS'!$A:$A,$A5,'BACKUP COUNTS'!$B:$B,F$1,'BACKUP COUNTS'!$G:$G,F$2)=0,"",SUMIFS('BACKUP COUNTS'!$F:$F,'BACKUP COUNTS'!$A:$A,$A5,'BACKUP COUNTS'!$B:$B,F$1,'BACKUP COUNTS'!$G:$G,F$2)) | G5: =IF(SUMIFS('BACKUP COUNTS'!$F:$F,'BACKUP COUNTS'!$A:$A,$A5,'BACKUP COUNTS'!$B:$B,G$1,'BACKUP COUNTS'!$G:$G,G$2)=0,"",SUMIFS('BACKUP COUNTS'!$F:$F,'BACKUP COUNTS'!$A:$A,$A5,'BACKUP COUNTS'!$B:$B,G$1,'BACKUP COUNTS'!$G:$G,G$2)) | H5: =IF(SUMIFS('BACKUP COUNTS'!$F:$F,'BACKUP COUNTS'!$A:$A,$A5,'BACKUP COUNTS'!$B:$B,H$1,'BACKUP COUNTS'!$G:$G,H$2)=0,"",SUMIFS('BACKUP COUNTS'!$F:$F,'BACKUP COUNTS'!$A:$A,$A5,'BACKUP COUNTS'!$B:$B,H$1,'BACKUP COUNTS'!$G:$G,H$2)) | I5: =IF(SUMIFS('BACKUP COUNTS'!$F:$F,'BACKUP COUNTS'!$A:$A,$A5,'BACKUP COUNTS'!$B:$B,I$1,'BACKUP COUNTS'!$G:$G,I$2)=0,"",SUMIFS('BACKUP COUNTS'!$F:$F,'BACKUP COUNTS'!$A:$A,$A5,'BACKUP COUNTS'!$B:$B,I$1,'BACKUP COUNTS'!$G:$G,I$2)) | J5: =IF(SUMIFS('BACKUP COUNTS'!$F:$F,'BACKUP COUNTS'!$A:$A,$A5,'BACKUP COUNTS'!$B:$B,J$1,'BACKUP COUNTS'!$G:$G,J$2)=0,"",SUMIFS('BACKUP COUNTS'!$F:$F,'BACKUP COUNTS'!$A:$A,$A5,'BACKUP COUNTS'!$B:$B,J$1,'BACKUP COUNTS'!$G:$G,J$2)) | K5: =IF(SUMIFS('BACKUP COUNTS'!$F:$F,'BACKUP COUNTS'!$A:$A,$A5,'BACKUP COUNTS'!$B:$B,K$1,'BACKUP COUNTS'!$G:$G,K$2)=0,"",SUMIFS('BACKUP COUNTS'!$F:$F,'BACKUP COUNTS'!$A:$A,$A5,'BACKUP COUNTS'!$B:$B,K$1,'BACKUP COUNTS'!$G:$G,K$2)) | ... R5: =IF(SUMIFS('BACKUP COUNTS'!$F:$F,'BACKUP COUNTS'!$A:$A,$A5,'BACKUP COUNTS'!$B:$B,R$1,'BACKUP COUNTS'!$G:$G,R$2)=0,"",SUMIFS('BACKUP COUNTS'!$F:$F,'BACKUP COUNTS'!$A:$A,$A5,'BACKUP COUNTS'!$B:$B,R$1,'BACKUP COUNTS'!$G:$G,R$2))
A6: =IF(WEEKDAY(A5,2)=5,A5+3,A5+1) -> 45841 | C6: =IF(SUMIFS('BACKUP COUNTS'!$F:$F,'BACKUP COUNTS'!$A:$A,$A6,'BACKUP COUNTS'!$B:$B,C$2)=0,"",SUMIFS('BACKUP COUNTS'!$F:$F,'BACKUP COUNTS'!$A:$A,$A6,'BACKUP COUNTS'!$B:$B,C$2)) | D6: =IF(SUMIFS('BACKUP COUNTS'!$F:$F,'BACKUP COUNTS'!$A:$A,$A6,'BACKUP COUNTS'!$B:$B,D$1,'BACKUP COUNTS'!$G:$G,D$2)=0,"",SUMIFS('BACKUP COUNTS'!$F:$F,'BACKUP COUNTS'!$A:$A,$A6,'BACKUP COUNTS'!$B:$B,D$1,'BACKUP COUNTS'!$G:$G,D$2)) | E6: =IF(SUMIFS('BACKUP COUNTS'!$F:$F,'BACKUP COUNTS'!$A:$A,$A6,'BACKUP COUNTS'!$B:$B,E$1,'BACKUP COUNTS'!$G:$G,E$2)=0,"",SUMIFS('BACKUP COUNTS'!$F:$F,'BACKUP COUNTS'!$A:$A,$A6,'BACKUP COUNTS'!$B:$B,E$1,'BACKUP COUNTS'!$G:$G,E$2)) | F6: =IF(SUMIFS('BACKUP COUNTS'!$F:$F,'BACKUP COUNTS'!$A:$A,$A6,'BACKUP COUNTS'!$B:$B,F$1,'BACKUP COUNTS'!$G:$G,F$2)=0,"",SUMIFS('BACKUP COUNTS'!$F:$F,'BACKUP COUNTS'!$A:$A,$A6,'BACKUP COUNTS'!$B:$B,F$1,'BACKUP COUNTS'!$G:$G,F$2)) | G6: =IF(SUMIFS('BACKUP COUNTS'!$F:$F,'BACKUP COUNTS'!$A:$A,$A6,'BACKUP COUNTS'!$B:$B,G$1,'BACKUP COUNTS'!$G:$G,G$2)=0,"",SUMIFS('BACKUP COUNTS'!$F:$F,'BACKUP COUNTS'!$A:$A,$A6,'BACKUP COUNTS'!$B:$B,G$1,'BACKUP COUNTS'!$G:$G,G$2)) | H6: =IF(SUMIFS('BACKUP COUNTS'!$F:$F,'BACKUP COUNTS'!$A:$A,$A6,'BACKUP COUNTS'!$B:$B,H$1,'BACKUP COUNTS'!$G:$G,H$2)=0,"",SUMIFS('BACKUP COUNTS'!$F:$F,'BACKUP COUNTS'!$A:$A,$A6,'BACKUP COUNTS'!$B:$B,H$1,'BACKUP COUNTS'!$G:$G,H$2)) | I6: =IF(SUMIFS('BACKUP COUNTS'!$F:$F,'BACKUP COUNTS'!$A:$A,$A6,'BACKUP COUNTS'!$B:$B,I$1,'BACKUP COUNTS'!$G:$G,I$2)=0,"",SUMIFS('BACKUP COUNTS'!$F:$F,'BACKUP COUNTS'!$A:$A,$A6,'BACKUP COUNTS'!$B:$B,I$1,'BACKUP COUNTS'!$G:$G,I$2)) | J6: =IF(SUMIFS('BACKUP COUNTS'!$F:$F,'BACKUP COUNTS'!$A:$A,$A6,'BACKUP COUNTS'!$B:$B,J$1,'BACKUP COUNTS'!$G:$G,J$2)=0,"",SUMIFS('BACKUP COUNTS'!$F:$F,'BACKUP COUNTS'!$A:$A,$A6,'BACKUP COUNTS'!$B:$B,J$1,'BACKUP COUNTS'!$G:$G,J$2)) | K6: =IF(SUMIFS('BACKUP COUNTS'!$F:$F,'BACKUP COUNTS'!$A:$A,$A6,'BACKUP COUNTS'!$B:$B,K$1,'BACKUP COUNTS'!$G:$G,K$2)=0,"",SUMIFS('BACKUP COUNTS'!$F:$F,'BACKUP COUNTS'!$A:$A,$A6,'BACKUP COUNTS'!$B:$B,K$1,'BACKUP COUNTS'!$G:$G,K$2)) | ... R6: =IF(SUMIFS('BACKUP COUNTS'!$F:$F,'BACKUP COUNTS'!$A:$A,$A6,'BACKUP COUNTS'!$B:$B,R$1,'BACKUP COUNTS'!$G:$G,R$2)=0,"",SUMIFS('BACKUP COUNTS'!$F:$F,'BACKUP COUNTS'!$A:$A,$A6,'BACKUP COUNTS'!$B:$B,R$1,'BACKUP COUNTS'!$G:$G,R$2))
A7: =IF(WEEKDAY(A6,2)=5,A6+3,A6+1) -> 45842 | C7: =IF(SUMIFS('BACKUP COUNTS'!$F:$F,'BACKUP COUNTS'!$A:$A,$A7,'BACKUP COUNTS'!$B:$B,C$2)=0,"",SUMIFS('BACKUP COUNTS'!$F:$F,'BACKUP COUNTS'!$A:$A,$A7,'BACKUP COUNTS'!$B:$B,C$2)) | D7: =IF(SUMIFS('BACKUP COUNTS'!$F:$F,'BACKUP COUNTS'!$A:$A,$A7,'BACKUP COUNTS'!$B:$B,D$1,'BACKUP COUNTS'!$G:$G,D$2)=0,"",SUMIFS('BACKUP COUNTS'!$F:$F,'BACKUP COUNTS'!$A:$A,$A7,'BACKUP COUNTS'!$B:$B,D$1,'BACKUP COUNTS'!$G:$G,D$2)) | E7: =IF(SUMIFS('BACKUP COUNTS'!$F:$F,'BACKUP COUNTS'!$A:$A,$A7,'BACKUP COUNTS'!$B:$B,E$1,'BACKUP COUNTS'!$G:$G,E$2)=0,"",SUMIFS('BACKUP COUNTS'!$F:$F,'BACKUP COUNTS'!$A:$A,$A7,'BACKUP COUNTS'!$B:$B,E$1,'BACKUP COUNTS'!$G:$G,E$2)) | F7: =IF(SUMIFS('BACKUP COUNTS'!$F:$F,'BACKUP COUNTS'!$A:$A,$A7,'BACKUP COUNTS'!$B:$B,F$1,'BACKUP COUNTS'!$G:$G,F$2)=0,"",SUMIFS('BACKUP COUNTS'!$F:$F,'BACKUP COUNTS'!$A:$A,$A7,'BACKUP COUNTS'!$B:$B,F$1,'BACKUP COUNTS'!$G:$G,F$2)) | G7: =IF(SUMIFS('BACKUP COUNTS'!$F:$F,'BACKUP COUNTS'!$A:$A,$A7,'BACKUP COUNTS'!$B:$B,G$1,'BACKUP COUNTS'!$G:$G,G$2)=0,"",SUMIFS('BACKUP COUNTS'!$F:$F,'BACKUP COUNTS'!$A:$A,$A7,'BACKUP COUNTS'!$B:$B,G$1,'BACKUP COUNTS'!$G:$G,G$2)) | H7: =IF(SUMIFS('BACKUP COUNTS'!$F:$F,'BACKUP COUNTS'!$A:$A,$A7,'BACKUP COUNTS'!$B:$B,H$1,'BACKUP COUNTS'!$G:$G,H$2)=0,"",SUMIFS('BACKUP COUNTS'!$F:$F,'BACKUP COUNTS'!$A:$A,$A7,'BACKUP COUNTS'!$B:$B,H$1,'BACKUP COUNTS'!$G:$G,H$2)) | I7: =IF(SUMIFS('BACKUP COUNTS'!$F:$F,'BACKUP COUNTS'!$A:$A,$A7,'BACKUP COUNTS'!$B:$B,I$1,'BACKUP COUNTS'!$G:$G,I$2)=0,"",SUMIFS('BACKUP COUNTS'!$F:$F,'BACKUP COUNTS'!$A:$A,$A7,'BACKUP COUNTS'!$B:$B,I$1,'BACKUP COUNTS'!$G:$G,I$2)) | J7: =IF(SUMIFS('BACKUP COUNTS'!$F:$F,'BACKUP COUNTS'!$A:$A,$A7,'BACKUP COUNTS'!$B:$B,J$1,'BACKUP COUNTS'!$G:$G,J$2)=0,"",SUMIFS('BACKUP COUNTS'!$F:$F,'BACKUP COUNTS'!$A:$A,$A7,'BACKUP COUNTS'!$B:$B,J$1,'BACKUP COUNTS'!$G:$G,J$2)) | K7: =IF(SUMIFS('BACKUP COUNTS'!$F:$F,'BACKUP COUNTS'!$A:$A,$A7,'BACKUP COUNTS'!$B:$B,K$1,'BACKUP COUNTS'!$G:$G,K$2)=0,"",SUMIFS('BACKUP COUNTS'!$F:$F,'BACKUP COUNTS'!$A:$A,$A7,'BACKUP COUNTS'!$B:$B,K$1,'BACKUP COUNTS'!$G:$G,K$2)) | ... R7: =IF(SUMIFS('BACKUP COUNTS'!$F:$F,'BACKUP COUNTS'!$A:$A,$A7,'BACKUP COUNTS'!$B:$B,R$1,'BACKUP COUNTS'!$G:$G,R$2)=0,"",SUMIFS('BACKUP COUNTS'!$F:$F,'BACKUP COUNTS'!$A:$A,$A7,'BACKUP COUNTS'!$B:$B,R$1,'BACKUP COUNTS'!$G:$G,R$2))
A8: =IF(WEEKDAY(A7,2)=5,A7+3,A7+1) -> 45845 | C8: =IF(SUMIFS('BACKUP COUNTS'!$F:$F,'BACKUP COUNTS'!$A:$A,$A8,'BACKUP COUNTS'!$B:$B,C$2)=0,"",SUMIFS('BACKUP COUNTS'!$F:$F,'BACKUP COUNTS'!$A:$A,$A8,'BACKUP COUNTS'!$B:$B,C$2)) | D8: =IF(SUMIFS('BACKUP COUNTS'!$F:$F,'BACKUP COUNTS'!$A:$A,$A8,'BACKUP COUNTS'!$B:$B,D$1,'BACKUP COUNTS'!$G:$G,D$2)=0,"",SUMIFS('BACKUP COUNTS'!$F:$F,'BACKUP COUNTS'!$A:$A,$A8,'BACKUP COUNTS'!$B:$B,D$1,'BACKUP COUNTS'!$G:$G,D$2)) | E8: =IF(SUMIFS('BACKUP COUNTS'!$F:$F,'BACKUP COUNTS'!$A:$A,$A8,'BACKUP COUNTS'!$B:$B,E$1,'BACKUP COUNTS'!$G:$G,E$2)=0,"",SUMIFS('BACKUP COUNTS'!$F:$F,'BACKUP COUNTS'!$A:$A,$A8,'BACKUP COUNTS'!$B:$B,E$1,'BACKUP COUNTS'!$G:$G,E$2)) | F8: =IF(SUMIFS('BACKUP COUNTS'!$F:$F,'BACKUP COUNTS'!$A:$A,$A8,'BACKUP COUNTS'!$B:$B,F$1,'BACKUP COUNTS'!$G:$G,F$2)=0,"",SUMIFS('BACKUP COUNTS'!$F:$F,'BACKUP COUNTS'!$A:$A,$A8,'BACKUP COUNTS'!$B:$B,F$1,'BACKUP COUNTS'!$G:$G,F$2)) | G8: =IF(SUMIFS('BACKUP COUNTS'!$F:$F,'BACKUP COUNTS'!$A:$A,$A8,'BACKUP COUNTS'!$B:$B,G$1,'BACKUP COUNTS'!$G:$G,G$2)=0,"",SUMIFS('BACKUP COUNTS'!$F:$F,'BACKUP COUNTS'!$A:$A,$A8,'BACKUP COUNTS'!$B:$B,G$1,'BACKUP COUNTS'!$G:$G,G$2)) | H8: =IF(SUMIFS('BACKUP COUNTS'!$F:$F,'BACKUP COUNTS'!$A:$A,$A8,'BACKUP COUNTS'!$B:$B,H$1,'BACKUP COUNTS'!$G:$G,H$2)=0,"",SUMIFS('BACKUP COUNTS'!$F:$F,'BACKUP COUNTS'!$A:$A,$A8,'BACKUP COUNTS'!$B:$B,H$1,'BACKUP COUNTS'!$G:$G,H$2)) | I8: =IF(SUMIFS('BACKUP COUNTS'!$F:$F,'BACKUP COUNTS'!$A:$A,$A8,'BACKUP COUNTS'!$B:$B,I$1,'BACKUP COUNTS'!$G:$G,I$2)=0,"",SUMIFS('BACKUP COUNTS'!$F:$F,'BACKUP COUNTS'!$A:$A,$A8,'BACKUP COUNTS'!$B:$B,I$1,'BACKUP COUNTS'!$G:$G,I$2)) | J8: =IF(SUMIFS('BACKUP COUNTS'!$F:$F,'BACKUP COUNTS'!$A:$A,$A8,'BACKUP COUNTS'!$B:$B,J$1,'BACKUP COUNTS'!$G:$G,J$2)=0,"",SUMIFS('BACKUP COUNTS'!$F:$F,'BACKUP COUNTS'!$A:$A,$A8,'BACKUP COUNTS'!$B:$B,J$1,'BACKUP COUNTS'!$G:$G,J$2)) | K8: =IF(SUMIFS('BACKUP COUNTS'!$F:$F,'BACKUP COUNTS'!$A:$A,$A8,'BACKUP COUNTS'!$B:$B,K$1,'BACKUP COUNTS'!$G:$G,K$2)=0,"",SUMIFS('BACKUP COUNTS'!$F:$F,'BACKUP COUNTS'!$A:$A,$A8,'BACKUP COUNTS'!$B:$B,K$1,'BACKUP COUNTS'!$G:$G,K$2)) | ... R8: =IF(SUMIFS('BACKUP COUNTS'!$F:$F,'BACKUP COUNTS'!$A:$A,$A8,'BACKUP COUNTS'!$B:$B,R$1,'BACKUP COUNTS'!$G:$G,R$2)=0,"",SUMIFS('BACKUP COUNTS'!$F:$F,'BACKUP COUNTS'!$A:$A,$A8,'BACKUP COUNTS'!$B:$B,R$1,'BACKUP COUNTS'!$G:$G,R$2))
A9: =IF(WEEKDAY(A8,2)=5,A8+3,A8+1) -> 45846 | C9: =IF(SUMIFS('BACKUP COUNTS'!$F:$F,'BACKUP COUNTS'!$A:$A,$A9,'BACKUP COUNTS'!$B:$B,C$2)=0,"",SUMIFS('BACKUP COUNTS'!$F:$F,'BACKUP COUNTS'!$A:$A,$A9,'BACKUP COUNTS'!$B:$B,C$2)) | D9: =IF(SUMIFS('BACKUP COUNTS'!$F:$F,'BACKUP COUNTS'!$A:$A,$A9,'BACKUP COUNTS'!$B:$B,D$1,'BACKUP COUNTS'!$G:$G,D$2)=0,"",SUMIFS('BACKUP COUNTS'!$F:$F,'BACKUP COUNTS'!$A:$A,$A9,'BACKUP COUNTS'!$B:$B,D$1,'BACKUP COUNTS'!$G:$G,D$2)) | E9: =IF(SUMIFS('BACKUP COUNTS'!$F:$F,'BACKUP COUNTS'!$A:$A,$A9,'BACKUP COUNTS'!$B:$B,E$1,'BACKUP COUNTS'!$G:$G,E$2)=0,"",SUMIFS('BACKUP COUNTS'!$F:$F,'BACKUP COUNTS'!$A:$A,$A9,'BACKUP COUNTS'!$B:$B,E$1,'BACKUP COUNTS'!$G:$G,E$2)) | F9: =IF(SUMIFS('BACKUP COUNTS'!$F:$F,'BACKUP COUNTS'!$A:$A,$A9,'BACKUP COUNTS'!$B:$B,F$1,'BACKUP COUNTS'!$G:$G,F$2)=0,"",SUMIFS('BACKUP COUNTS'!$F:$F,'BACKUP COUNTS'!$A:$A,$A9,'BACKUP COUNTS'!$B:$B,F$1,'BACKUP COUNTS'!$G:$G,F$2)) | G9: =IF(SUMIFS('BACKUP COUNTS'!$F:$F,'BACKUP COUNTS'!$A:$A,$A9,'BACKUP COUNTS'!$B:$B,G$1,'BACKUP COUNTS'!$G:$G,G$2)=0,"",SUMIFS('BACKUP COUNTS'!$F:$F,'BACKUP COUNTS'!$A:$A,$A9,'BACKUP COUNTS'!$B:$B,G$1,'BACKUP COUNTS'!$G:$G,G$2)) | H9: =IF(SUMIFS('BACKUP COUNTS'!$F:$F,'BACKUP COUNTS'!$A:$A,$A9,'BACKUP COUNTS'!$B:$B,H$1,'BACKUP COUNTS'!$G:$G,H$2)=0,"",SUMIFS('BACKUP COUNTS'!$F:$F,'BACKUP COUNTS'!$A:$A,$A9,'BACKUP COUNTS'!$B:$B,H$1,'BACKUP COUNTS'!$G:$G,H$2)) | I9: =IF(SUMIFS('BACKUP COUNTS'!$F:$F,'BACKUP COUNTS'!$A:$A,$A9,'BACKUP COUNTS'!$B:$B,I$1,'BACKUP COUNTS'!$G:$G,I$2)=0,"",SUMIFS('BACKUP COUNTS'!$F:$F,'BACKUP COUNTS'!$A:$A,$A9,'BACKUP COUNTS'!$B:$B,I$1,'BACKUP COUNTS'!$G:$G,I$2)) | J9: =IF(SUMIFS('BACKUP COUNTS'!$F:$F,'BACKUP COUNTS'!$A:$A,$A9,'BACKUP COUNTS'!$B:$B,J$1,'BACKUP COUNTS'!$G:$G,J$2)=0,"",SUMIFS('BACKUP COUNTS'!$F:$F,'BACKUP COUNTS'!$A:$A,$A9,'BACKUP COUNTS'!$B:$B,J$1,'BACKUP COUNTS'!$G:$G,J$2)) | K9: =IF(SUMIFS('BACKUP COUNTS'!$F:$F,'BACKUP COUNTS'!$A:$A,$A9,'BACKUP COUNTS'!$B:$B,K$1,'BACKUP COUNTS'!$G:$G,K$2)=0,"",SUMIFS('BACKUP COUNTS'!$F:$F,'BACKUP COUNTS'!$A:$A,$A9,'BACKUP COUNTS'!$B:$B,K$1,'BACKUP COUNTS'!$G:$G,K$2)) | ... R9: =IF(SUMIFS('BACKUP COUNTS'!$F:$F,'BACKUP COUNTS'!$A:$A,$A9,'BACKUP COUNTS'!$B:$B,R$1,'BACKUP COUNTS'!$G:$G,R$2)=0,"",SUMIFS('BACKUP COUNTS'!$F:$F,'BACKUP COUNTS'!$A:$A,$A9,'BACKUP COUNTS'!$B:$B,R$1,'BACKUP COUNTS'!$G:$G,R$2))
A10: =IF(WEEKDAY(A9,2)=5,A9+3,A9+1) -> 45847 | C10: =IF(SUMIFS('BACKUP COUNTS'!$F:$F,'BACKUP COUNTS'!$A:$A,$A10,'BACKUP COUNTS'!$B:$B,C$2)=0,"",SUMIFS('BACKUP COUNTS'!$F:$F,'BACKUP COUNTS'!$A:$A,$A10,'BACKUP COUNTS'!$B:$B,C$2)) | D10: =IF(SUMIFS('BACKUP COUNTS'!$F:$F,'BACKUP COUNTS'!$A:$A,$A10,'BACKUP COUNTS'!$B:$B,D$1,'BACKUP COUNTS'!$G:$G,D$2)=0,"",SUMIFS('BACKUP COUNTS'!$F:$F,'BACKUP COUNTS'!$A:$A,$A10,'BACKUP COUNTS'!$B:$B,D$1,'BACKUP COUNTS'!$G:$G,D$2)) | E10: =IF(SUMIFS('BACKUP COUNTS'!$F:$F,'BACKUP COUNTS'!$A:$A,$A10,'BACKUP COUNTS'!$B:$B,E$1,'BACKUP COUNTS'!$G:$G,E$2)=0,"",SUMIFS('BACKUP COUNTS'!$F:$F,'BACKUP COUNTS'!$A:$A,$A10,'BACKUP COUNTS'!$B:$B,E$1,'BACKUP COUNTS'!$G:$G,E$2)) | F10: =IF(SUMIFS('BACKUP COUNTS'!$F:$F,'BACKUP COUNTS'!$A:$A,$A10,'BACKUP COUNTS'!$B:$B,F$1,'BACKUP COUNTS'!$G:$G,F$2)=0,"",SUMIFS('BACKUP COUNTS'!$F:$F,'BACKUP COUNTS'!$A:$A,$A10,'BACKUP COUNTS'!$B:$B,F$1,'BACKUP COUNTS'!$G:$G,F$2)) | G10: =IF(SUMIFS('BACKUP COUNTS'!$F:$F,'BACKUP COUNTS'!$A:$A,$A10,'BACKUP COUNTS'!$B:$B,G$1,'BACKUP COUNTS'!$G:$G,G$2)=0,"",SUMIFS('BACKUP COUNTS'!$F:$F,'BACKUP COUNTS'!$A:$A,$A10,'BACKUP COUNTS'!$B:$B,G$1,'BACKUP COUNTS'!$G:$G,G$2)) | H10: =IF(SUMIFS('BACKUP COUNTS'!$F:$F,'BACKUP COUNTS'!$A:$A,$A10,'BACKUP COUNTS'!$B:$B,H$1,'BACKUP COUNTS'!$G:$G,H$2)=0,"",SUMIFS('BACKUP COUNTS'!$F:$F,'BACKUP COUNTS'!$A:$A,$A10,'BACKUP COUNTS'!$B:$B,H$1,'BACKUP COUNTS'!$G:$G,H$2)) | I10: =IF(SUMIFS('BACKUP COUNTS'!$F:$F,'BACKUP COUNTS'!$A:$A,$A10,'BACKUP COUNTS'!$B:$B,I$1,'BACKUP COUNTS'!$G:$G,I$2)=0,"",SUMIFS('BACKUP COUNTS'!$F:$F,'BACKUP COUNTS'!$A:$A,$A10,'BACKUP COUNTS'!$B:$B,I$1,'BACKUP COUNTS'!$G:$G,I$2)) | J10: =IF(SUMIFS('BACKUP COUNTS'!$F:$F,'BACKUP COUNTS'!$A:$A,$A10,'BACKUP COUNTS'!$B:$B,J$1,'BACKUP COUNTS'!$G:$G,J$2)=0,"",SUMIFS('BACKUP COUNTS'!$F:$F,'BACKUP COUNTS'!$A:$A,$A10,'BACKUP COUNTS'!$B:$B,J$1,'BACKUP COUNTS'!$G:$G,J$2)) | K10: =IF(SUMIFS('BACKUP COUNTS'!$F:$F,'BACKUP COUNTS'!$A:$A,$A10,'BACKUP COUNTS'!$B:$B,K$1,'BACKUP COUNTS'!$G:$G,K$2)=0,"",SUMIFS('BACKUP COUNTS'!$F:$F,'BACKUP COUNTS'!$A:$A,$A10,'BACKUP COUNTS'!$B:$B,K$1,'BACKUP COUNTS'!$G:$G,K$2)) | ... R10: =IF(SUMIFS('BACKUP COUNTS'!$F:$F,'BACKUP COUNTS'!$A:$A,$A10,'BACKUP COUNTS'!$B:$B,R$1,'BACKUP COUNTS'!$G:$G,R$2)=0,"",SUMIFS('BACKUP COUNTS'!$F:$F,'BACKUP COUNTS'!$A:$A,$A10,'BACKUP COUNTS'!$B:$B,R$1,'BACKUP COUNTS'!$G:$G,R$2))
A11: =IF(WEEKDAY(A10,2)=5,A10+3,A10+1) -> 45848 | C11: =IF(SUMIFS('BACKUP COUNTS'!$F:$F,'BACKUP COUNTS'!$A:$A,$A11,'BACKUP COUNTS'!$B:$B,C$2)=0,"",SUMIFS('BACKUP COUNTS'!$F:$F,'BACKUP COUNTS'!$A:$A,$A11,'BACKUP COUNTS'!$B:$B,C$2)) | D11: =IF(SUMIFS('BACKUP COUNTS'!$F:$F,'BACKUP COUNTS'!$A:$A,$A11,'BACKUP COUNTS'!$B:$B,D$1,'BACKUP COUNTS'!$G:$G,D$2)=0,"",SUMIFS('BACKUP COUNTS'!$F:$F,'BACKUP COUNTS'!$A:$A,$A11,'BACKUP COUNTS'!$B:$B,D$1,'BACKUP COUNTS'!$G:$G,D$2)) | E11: =IF(SUMIFS('BACKUP COUNTS'!$F:$F,'BACKUP COUNTS'!$A:$A,$A11,'BACKUP COUNTS'!$B:$B,E$1,'BACKUP COUNTS'!$G:$G,E$2)=0,"",SUMIFS('BACKUP COUNTS'!$F:$F,'BACKUP COUNTS'!$A:$A,$A11,'BACKUP COUNTS'!$B:$B,E$1,'BACKUP COUNTS'!$G:$G,E$2)) | F11: =IF(SUMIFS('BACKUP COUNTS'!$F:$F,'BACKUP COUNTS'!$A:$A,$A11,'BACKUP COUNTS'!$B:$B,F$1,'BACKUP COUNTS'!$G:$G,F$2)=0,"",SUMIFS('BACKUP COUNTS'!$F:$F,'BACKUP COUNTS'!$A:$A,$A11,'BACKUP COUNTS'!$B:$B,F$1,'BACKUP COUNTS'!$G:$G,F$2)) | G11: =IF(SUMIFS('BACKUP COUNTS'!$F:$F,'BACKUP COUNTS'!$A:$A,$A11,'BACKUP COUNTS'!$B:$B,G$1,'BACKUP COUNTS'!$G:$G,G$2)=0,"",SUMIFS('BACKUP COUNTS'!$F:$F,'BACKUP COUNTS'!$A:$A,$A11,'BACKUP COUNTS'!$B:$B,G$1,'BACKUP COUNTS'!$G:$G,G$2)) | H11: =IF(SUMIFS('BACKUP COUNTS'!$F:$F,'BACKUP COUNTS'!$A:$A,$A11,'BACKUP COUNTS'!$B:$B,H$1,'BACKUP COUNTS'!$G:$G,H$2)=0,"",SUMIFS('BACKUP COUNTS'!$F:$F,'BACKUP COUNTS'!$A:$A,$A11,'BACKUP COUNTS'!$B:$B,H$1,'BACKUP COUNTS'!$G:$G,H$2)) | I11: =IF(SUMIFS('BACKUP COUNTS'!$F:$F,'BACKUP COUNTS'!$A:$A,$A11,'BACKUP COUNTS'!$B:$B,I$1,'BACKUP COUNTS'!$G:$G,I$2)=0,"",SUMIFS('BACKUP COUNTS'!$F:$F,'BACKUP COUNTS'!$A:$A,$A11,'BACKUP COUNTS'!$B:$B,I$1,'BACKUP COUNTS'!$G:$G,I$2)) | J11: =IF(SUMIFS('BACKUP COUNTS'!$F:$F,'BACKUP COUNTS'!$A:$A,$A11,'BACKUP COUNTS'!$B:$B,J$1,'BACKUP COUNTS'!$G:$G,J$2)=0,"",SUMIFS('BACKUP COUNTS'!$F:$F,'BACKUP COUNTS'!$A:$A,$A11,'BACKUP COUNTS'!$B:$B,J$1,'BACKUP COUNTS'!$G:$G,J$2)) | K11: =IF(SUMIFS('BACKUP COUNTS'!$F:$F,'BACKUP COUNTS'!$A:$A,$A11,'BACKUP COUNTS'!$B:$B,K$1,'BACKUP COUNTS'!$G:$G,K$2)=0,"",SUMIFS('BACKUP COUNTS'!$F:$F,'BACKUP COUNTS'!$A:$A,$A11,'BACKUP COUNTS'!$B:$B,K$1,'BACKUP COUNTS'!$G:$G,K$2)) | ... R11: =IF(SUMIFS('BACKUP COUNTS'!$F:$F,'BACKUP COUNTS'!$A:$A,$A11,'BACKUP COUNTS'!$B:$B,R$1,'BACKUP COUNTS'!$G:$G,R$2)=0,"",SUMIFS('BACKUP COUNTS'!$F:$F,'BACKUP COUNTS'!$A:$A,$A11,'BACKUP COUNTS'!$B:$B,R$1,'BACKUP COUNTS'!$G:$G,R$2))
A12: =IF(WEEKDAY(A11,2)=5,A11+3,A11+1) -> 45849 | C12: =IF(SUMIFS('BACKUP COUNTS'!$F:$F,'BACKUP COUNTS'!$A:$A,$A12,'BACKUP COUNTS'!$B:$B,C$2)=0,"",SUMIFS('BACKUP COUNTS'!$F:$F,'BACKUP COUNTS'!$A:$A,$A12,'BACKUP COUNTS'!$B:$B,C$2)) | D12: =IF(SUMIFS('BACKUP COUNTS'!$F:$F,'BACKUP COUNTS'!$A:$A,$A12,'BACKUP COUNTS'!$B:$B,D$1,'BACKUP COUNTS'!$G:$G,D$2)=0,"",SUMIFS('BACKUP COUNTS'!$F:$F,'BACKUP COUNTS'!$A:$A,$A12,'BACKUP COUNTS'!$B:$B,D$1,'BACKUP COUNTS'!$G:$G,D$2)) | E12: =IF(SUMIFS('BACKUP COUNTS'!$F:$F,'BACKUP COUNTS'!$A:$A,$A12,'BACKUP COUNTS'!$B:$B,E$1,'BACKUP COUNTS'!$G:$G,E$2)=0,"",SUMIFS('BACKUP COUNTS'!$F:$F,'BACKUP COUNTS'!$A:$A,$A12,'BACKUP COUNTS'!$B:$B,E$1,'BACKUP COUNTS'!$G:$G,E$2)) | F12: =IF(SUMIFS('BACKUP COUNTS'!$F:$F,'BACKUP COUNTS'!$A:$A,$A12,'BACKUP COUNTS'!$B:$B,F$1,'BACKUP COUNTS'!$G:$G,F$2)=0,"",SUMIFS('BACKUP COUNTS'!$F:$F,'BACKUP COUNTS'!$A:$A,$A12,'BACKUP COUNTS'!$B:$B,F$1,'BACKUP COUNTS'!$G:$G,F$2)) | G12: =IF(SUMIFS('BACKUP COUNTS'!$F:$F,'BACKUP COUNTS'!$A:$A,$A12,'BACKUP COUNTS'!$B:$B,G$1,'BACKUP COUNTS'!$G:$G,G$2)=0,"",SUMIFS('BACKUP COUNTS'!$F:$F,'BACKUP COUNTS'!$A:$A,$A12,'BACKUP COUNTS'!$B:$B,G$1,'BACKUP COUNTS'!$G:$G,G$2)) | H12: =IF(SUMIFS('BACKUP COUNTS'!$F:$F,'BACKUP COUNTS'!$A:$A,$A12,'BACKUP COUNTS'!$B:$B,H$1,'BACKUP COUNTS'!$G:$G,H$2)=0,"",SUMIFS('BACKUP COUNTS'!$F:$F,'BACKUP COUNTS'!$A:$A,$A12,'BACKUP COUNTS'!$B:$B,H$1,'BACKUP COUNTS'!$G:$G,H$2)) | I12: =IF(SUMIFS('BACKUP COUNTS'!$F:$F,'BACKUP COUNTS'!$A:$A,$A12,'BACKUP COUNTS'!$B:$B,I$1,'BACKUP COUNTS'!$G:$G,I$2)=0,"",SUMIFS('BACKUP COUNTS'!$F:$F,'BACKUP COUNTS'!$A:$A,$A12,'BACKUP COUNTS'!$B:$B,I$1,'BACKUP COUNTS'!$G:$G,I$2)) | J12: =IF(SUMIFS('BACKUP COUNTS'!$F:$F,'BACKUP COUNTS'!$A:$A,$A12,'BACKUP COUNTS'!$B:$B,J$1,'BACKUP COUNTS'!$G:$G,J$2)=0,"",SUMIFS('BACKUP COUNTS'!$F:$F,'BACKUP COUNTS'!$A:$A,$A12,'BACKUP COUNTS'!$B:$B,J$1,'BACKUP COUNTS'!$G:$G,J$2)) | K12: =IF(SUMIFS('BACKUP COUNTS'!$F:$F,'BACKUP COUNTS'!$A:$A,$A12,'BACKUP COUNTS'!$B:$B,K$1,'BACKUP COUNTS'!$G:$G,K$2)=0,"",SUMIFS('BACKUP COUNTS'!$F:$F,'BACKUP COUNTS'!$A:$A,$A12,'BACKUP COUNTS'!$B:$B,K$1,'BACKUP COUNTS'!$G:$G,K$2)) | ... R12: =IF(SUMIFS('BACKUP COUNTS'!$F:$F,'BACKUP COUNTS'!$A:$A,$A12,'BACKUP COUNTS'!$B:$B,R$1,'BACKUP COUNTS'!$G:$G,R$2)=0,"",SUMIFS('BACKUP COUNTS'!$F:$F,'BACKUP COUNTS'!$A:$A,$A12,'BACKUP COUNTS'!$B:$B,R$1,'BACKUP COUNTS'!$G:$G,R$2))
A13: =IF(WEEKDAY(A12,2)=5,A12+3,A12+1) -> 45852 | C13: =IF(SUMIFS('BACKUP COUNTS'!$F:$F,'BACKUP COUNTS'!$A:$A,$A13,'BACKUP COUNTS'!$B:$B,C$2)=0,"",SUMIFS('BACKUP COUNTS'!$F:$F,'BACKUP COUNTS'!$A:$A,$A13,'BACKUP COUNTS'!$B:$B,C$2)) | D13: =IF(SUMIFS('BACKUP COUNTS'!$F:$F,'BACKUP COUNTS'!$A:$A,$A13,'BACKUP COUNTS'!$B:$B,D$1,'BACKUP COUNTS'!$G:$G,D$2)=0,"",SUMIFS('BACKUP COUNTS'!$F:$F,'BACKUP COUNTS'!$A:$A,$A13,'BACKUP COUNTS'!$B:$B,D$1,'BACKUP COUNTS'!$G:$G,D$2)) | E13: =IF(SUMIFS('BACKUP COUNTS'!$F:$F,'BACKUP COUNTS'!$A:$A,$A13,'BACKUP COUNTS'!$B:$B,E$1,'BACKUP COUNTS'!$G:$G,E$2)=0,"",SUMIFS('BACKUP COUNTS'!$F:$F,'BACKUP COUNTS'!$A:$A,$A13,'BACKUP COUNTS'!$B:$B,E$1,'BACKUP COUNTS'!$G:$G,E$2)) | F13: =IF(SUMIFS('BACKUP COUNTS'!$F:$F,'BACKUP COUNTS'!$A:$A,$A13,'BACKUP COUNTS'!$B:$B,F$1,'BACKUP COUNTS'!$G:$G,F$2)=0,"",SUMIFS('BACKUP COUNTS'!$F:$F,'BACKUP COUNTS'!$A:$A,$A13,'BACKUP COUNTS'!$B:$B,F$1,'BACKUP COUNTS'!$G:$G,F$2)) | G13: =IF(SUMIFS('BACKUP COUNTS'!$F:$F,'BACKUP COUNTS'!$A:$A,$A13,'BACKUP COUNTS'!$B:$B,G$1,'BACKUP COUNTS'!$G:$G,G$2)=0,"",SUMIFS('BACKUP COUNTS'!$F:$F,'BACKUP COUNTS'!$A:$A,$A13,'BACKUP COUNTS'!$B:$B,G$1,'BACKUP COUNTS'!$G:$G,G$2)) | H13: =IF(SUMIFS('BACKUP COUNTS'!$F:$F,'BACKUP COUNTS'!$A:$A,$A13,'BACKUP COUNTS'!$B:$B,H$1,'BACKUP COUNTS'!$G:$G,H$2)=0,"",SUMIFS('BACKUP COUNTS'!$F:$F,'BACKUP COUNTS'!$A:$A,$A13,'BACKUP COUNTS'!$B:$B,H$1,'BACKUP COUNTS'!$G:$G,H$2)) | I13: =IF(SUMIFS('BACKUP COUNTS'!$F:$F,'BACKUP COUNTS'!$A:$A,$A13,'BACKUP COUNTS'!$B:$B,I$1,'BACKUP COUNTS'!$G:$G,I$2)=0,"",SUMIFS('BACKUP COUNTS'!$F:$F,'BACKUP COUNTS'!$A:$A,$A13,'BACKUP COUNTS'!$B:$B,I$1,'BACKUP COUNTS'!$G:$G,I$2)) | J13: =IF(SUMIFS('BACKUP COUNTS'!$F:$F,'BACKUP COUNTS'!$A:$A,$A13,'BACKUP COUNTS'!$B:$B,J$1,'BACKUP COUNTS'!$G:$G,J$2)=0,"",SUMIFS('BACKUP COUNTS'!$F:$F,'BACKUP COUNTS'!$A:$A,$A13,'BACKUP COUNTS'!$B:$B,J$1,'BACKUP COUNTS'!$G:$G,J$2)) | K13: =IF(SUMIFS('BACKUP COUNTS'!$F:$F,'BACKUP COUNTS'!$A:$A,$A13,'BACKUP COUNTS'!$B:$B,K$1,'BACKUP COUNTS'!$G:$G,K$2)=0,"",SUMIFS('BACKUP COUNTS'!$F:$F,'BACKUP COUNTS'!$A:$A,$A13,'BACKUP COUNTS'!$B:$B,K$1,'BACKUP COUNTS'!$G:$G,K$2)) | ... R13: =IF(SUMIFS('BACKUP COUNTS'!$F:$F,'BACKUP COUNTS'!$A:$A,$A13,'BACKUP COUNTS'!$B:$B,R$1,'BACKUP COUNTS'!$G:$G,R$2)=0,"",SUMIFS('BACKUP COUNTS'!$F:$F,'BACKUP COUNTS'!$A:$A,$A13,'BACKUP COUNTS'!$B:$B,R$1,'BACKUP COUNTS'!$G:$G,R$2))
A14: =IF(WEEKDAY(A13,2)=5,A13+3,A13+1) -> 45853 | C14: =IF(SUMIFS('BACKUP COUNTS'!$F:$F,'BACKUP COUNTS'!$A:$A,$A14,'BACKUP COUNTS'!$B:$B,C$2)=0,"",SUMIFS('BACKUP COUNTS'!$F:$F,'BACKUP COUNTS'!$A:$A,$A14,'BACKUP COUNTS'!$B:$B,C$2)) | D14: =IF(SUMIFS('BACKUP COUNTS'!$F:$F,'BACKUP COUNTS'!$A:$A,$A14,'BACKUP COUNTS'!$B:$B,D$1,'BACKUP COUNTS'!$G:$G,D$2)=0,"",SUMIFS('BACKUP COUNTS'!$F:$F,'BACKUP COUNTS'!$A:$A,$A14,'BACKUP COUNTS'!$B:$B,D$1,'BACKUP COUNTS'!$G:$G,D$2)) | E14: =IF(SUMIFS('BACKUP COUNTS'!$F:$F,'BACKUP COUNTS'!$A:$A,$A14,'BACKUP COUNTS'!$B:$B,E$1,'BACKUP COUNTS'!$G:$G,E$2)=0,"",SUMIFS('BACKUP COUNTS'!$F:$F,'BACKUP COUNTS'!$A:$A,$A14,'BACKUP COUNTS'!$B:$B,E$1,'BACKUP COUNTS'!$G:$G,E$2)) | F14: =IF(SUMIFS('BACKUP COUNTS'!$F:$F,'BACKUP COUNTS'!$A:$A,$A14,'BACKUP COUNTS'!$B:$B,F$1,'BACKUP COUNTS'!$G:$G,F$2)=0,"",SUMIFS('BACKUP COUNTS'!$F:$F,'BACKUP COUNTS'!$A:$A,$A14,'BACKUP COUNTS'!$B:$B,F$1,'BACKUP COUNTS'!$G:$G,F$2)) | G14: =IF(SUMIFS('BACKUP COUNTS'!$F:$F,'BACKUP COUNTS'!$A:$A,$A14,'BACKUP COUNTS'!$B:$B,G$1,'BACKUP COUNTS'!$G:$G,G$2)=0,"",SUMIFS('BACKUP COUNTS'!$F:$F,'BACKUP COUNTS'!$A:$A,$A14,'BACKUP COUNTS'!$B:$B,G$1,'BACKUP COUNTS'!$G:$G,G$2)) | H14: =IF(SUMIFS('BACKUP COUNTS'!$F:$F,'BACKUP COUNTS'!$A:$A,$A14,'BACKUP COUNTS'!$B:$B,H$1,'BACKUP COUNTS'!$G:$G,H$2)=0,"",SUMIFS('BACKUP COUNTS'!$F:$F,'BACKUP COUNTS'!$A:$A,$A14,'BACKUP COUNTS'!$B:$B,H$1,'BACKUP COUNTS'!$G:$G,H$2)) | I14: =IF(SUMIFS('BACKUP COUNTS'!$F:$F,'BACKUP COUNTS'!$A:$A,$A14,'BACKUP COUNTS'!$B:$B,I$1,'BACKUP COUNTS'!$G:$G,I$2)=0,"",SUMIFS('BACKUP COUNTS'!$F:$F,'BACKUP COUNTS'!$A:$A,$A14,'BACKUP COUNTS'!$B:$B,I$1,'BACKUP COUNTS'!$G:$G,I$2)) | J14: =IF(SUMIFS('BACKUP COUNTS'!$F:$F,'BACKUP COUNTS'!$A:$A,$A14,'BACKUP COUNTS'!$B:$B,J$1,'BACKUP COUNTS'!$G:$G,J$2)=0,"",SUMIFS('BACKUP COUNTS'!$F:$F,'BACKUP COUNTS'!$A:$A,$A14,'BACKUP COUNTS'!$B:$B,J$1,'BACKUP COUNTS'!$G:$G,J$2)) | K14: =IF(SUMIFS('BACKUP COUNTS'!$F:$F,'BACKUP COUNTS'!$A:$A,$A14,'BACKUP COUNTS'!$B:$B,K$1,'BACKUP COUNTS'!$G:$G,K$2)=0,"",SUMIFS('BACKUP COUNTS'!$F:$F,'BACKUP COUNTS'!$A:$A,$A14,'BACKUP COUNTS'!$B:$B,K$1,'BACKUP COUNTS'!$G:$G,K$2)) | ... R14: =IF(SUMIFS('BACKUP COUNTS'!$F:$F,'BACKUP COUNTS'!$A:$A,$A14,'BACKUP COUNTS'!$B:$B,R$1,'BACKUP COUNTS'!$G:$G,R$2)=0,"",SUMIFS('BACKUP COUNTS'!$F:$F,'BACKUP COUNTS'!$A:$A,$A14,'BACKUP COUNTS'!$B:$B,R$1,'BACKUP COUNTS'!$G:$G,R$2))
A15: =IF(WEEKDAY(A14,2)=5,A14+3,A14+1) -> 45854 | C15: =IF(SUMIFS('BACKUP COUNTS'!$F:$F,'BACKUP COUNTS'!$A:$A,$A15,'BACKUP COUNTS'!$B:$B,C$2)=0,"",SUMIFS('BACKUP COUNTS'!$F:$F,'BACKUP COUNTS'!$A:$A,$A15,'BACKUP COUNTS'!$B:$B,C$2)) | D15: =IF(SUMIFS('BACKUP COUNTS'!$F:$F,'BACKUP COUNTS'!$A:$A,$A15,'BACKUP COUNTS'!$B:$B,D$1,'BACKUP COUNTS'!$G:$G,D$2)=0,"",SUMIFS('BACKUP COUNTS'!$F:$F,'BACKUP COUNTS'!$A:$A,$A15,'BACKUP COUNTS'!$B:$B,D$1,'BACKUP COUNTS'!$G:$G,D$2)) | E15: =IF(SUMIFS('BACKUP COUNTS'!$F:$F,'BACKUP COUNTS'!$A:$A,$A15,'BACKUP COUNTS'!$B:$B,E$1,'BACKUP COUNTS'!$G:$G,E$2)=0,"",SUMIFS('BACKUP COUNTS'!$F:$F,'BACKUP COUNTS'!$A:$A,$A15,'BACKUP COUNTS'!$B:$B,E$1,'BACKUP COUNTS'!$G:$G,E$2)) | F15: =IF(SUMIFS('BACKUP COUNTS'!$F:$F,'BACKUP COUNTS'!$A:$A,$A15,'BACKUP COUNTS'!$B:$B,F$1,'BACKUP COUNTS'!$G:$G,F$2)=0,"",SUMIFS('BACKUP COUNTS'!$F:$F,'BACKUP COUNTS'!$A:$A,$A15,'BACKUP COUNTS'!$B:$B,F$1,'BACKUP COUNTS'!$G:$G,F$2)) | G15: =IF(SUMIFS('BACKUP COUNTS'!$F:$F,'BACKUP COUNTS'!$A:$A,$A15,'BACKUP COUNTS'!$B:$B,G$1,'BACKUP COUNTS'!$G:$G,G$2)=0,"",SUMIFS('BACKUP COUNTS'!$F:$F,'BACKUP COUNTS'!$A:$A,$A15,'BACKUP COUNTS'!$B:$B,G$1,'BACKUP COUNTS'!$G:$G,G$2)) | H15: =IF(SUMIFS('BACKUP COUNTS'!$F:$F,'BACKUP COUNTS'!$A:$A,$A15,'BACKUP COUNTS'!$B:$B,H$1,'BACKUP COUNTS'!$G:$G,H$2)=0,"",SUMIFS('BACKUP COUNTS'!$F:$F,'BACKUP COUNTS'!$A:$A,$A15,'BACKUP COUNTS'!$B:$B,H$1,'BACKUP COUNTS'!$G:$G,H$2)) | I15: =IF(SUMIFS('BACKUP COUNTS'!$F:$F,'BACKUP COUNTS'!$A:$A,$A15,'BACKUP COUNTS'!$B:$B,I$1,'BACKUP COUNTS'!$G:$G,I$2)=0,"",SUMIFS('BACKUP COUNTS'!$F:$F,'BACKUP COUNTS'!$A:$A,$A15,'BACKUP COUNTS'!$B:$B,I$1,'BACKUP COUNTS'!$G:$G,I$2)) | J15: =IF(SUMIFS('BACKUP COUNTS'!$F:$F,'BACKUP COUNTS'!$A:$A,$A15,'BACKUP COUNTS'!$B:$B,J$1,'BACKUP COUNTS'!$G:$G,J$2)=0,"",SUMIFS('BACKUP COUNTS'!$F:$F,'BACKUP COUNTS'!$A:$A,$A15,'BACKUP COUNTS'!$B:$B,J$1,'BACKUP COUNTS'!$G:$G,J$2)) | K15: =IF(SUMIFS('BACKUP COUNTS'!$F:$F,'BACKUP COUNTS'!$A:$A,$A15,'BACKUP COUNTS'!$B:$B,K$1,'BACKUP COUNTS'!$G:$G,K$2)=0,"",SUMIFS('BACKUP COUNTS'!$F:$F,'BACKUP COUNTS'!$A:$A,$A15,'BACKUP COUNTS'!$B:$B,K$1,'BACKUP COUNTS'!$G:$G,K$2)) | ... R15: =IF(SUMIFS('BACKUP COUNTS'!$F:$F,'BACKUP COUNTS'!$A:$A,$A15,'BACKUP COUNTS'!$B:$B,R$1,'BACKUP COUNTS'!$G:$G,R$2)=0,"",SUMIFS('BACKUP COUNTS'!$F:$F,'BACKUP COUNTS'!$A:$A,$A15,'BACKUP COUNTS'!$B:$B,R$1,'BACKUP COUNTS'!$G:$G,R$2))
A16: =IF(WEEKDAY(A15,2)=5,A15+3,A15+1) -> 45855 | C16: =IF(SUMIFS('BACKUP COUNTS'!$F:$F,'BACKUP COUNTS'!$A:$A,$A16,'BACKUP COUNTS'!$B:$B,C$2)=0,"",SUMIFS('BACKUP COUNTS'!$F:$F,'BACKUP COUNTS'!$A:$A,$A16,'BACKUP COUNTS'!$B:$B,C$2)) | D16: =IF(SUMIFS('BACKUP COUNTS'!$F:$F,'BACKUP COUNTS'!$A:$A,$A16,'BACKUP COUNTS'!$B:$B,D$1,'BACKUP COUNTS'!$G:$G,D$2)=0,"",SUMIFS('BACKUP COUNTS'!$F:$F,'BACKUP COUNTS'!$A:$A,$A16,'BACKUP COUNTS'!$B:$B,D$1,'BACKUP COUNTS'!$G:$G,D$2)) | E16: =IF(SUMIFS('BACKUP COUNTS'!$F:$F,'BACKUP COUNTS'!$A:$A,$A16,'BACKUP COUNTS'!$B:$B,E$1,'BACKUP COUNTS'!$G:$G,E$2)=0,"",SUMIFS('BACKUP COUNTS'!$F:$F,'BACKUP COUNTS'!$A:$A,$A16,'BACKUP COUNTS'!$B:$B,E$1,'BACKUP COUNTS'!$G:$G,E$2)) | F16: =IF(SUMIFS('BACKUP COUNTS'!$F:$F,'BACKUP COUNTS'!$A:$A,$A16,'BACKUP COUNTS'!$B:$B,F$1,'BACKUP COUNTS'!$G:$G,F$2)=0,"",SUMIFS('BACKUP COUNTS'!$F:$F,'BACKUP COUNTS'!$A:$A,$A16,'BACKUP COUNTS'!$B:$B,F$1,'BACKUP COUNTS'!$G:$G,F$2)) | G16: =IF(SUMIFS('BACKUP COUNTS'!$F:$F,'BACKUP COUNTS'!$A:$A,$A16,'BACKUP COUNTS'!$B:$B,G$1,'BACKUP COUNTS'!$G:$G,G$2)=0,"",SUMIFS('BACKUP COUNTS'!$F:$F,'BACKUP COUNTS'!$A:$A,$A16,'BACKUP COUNTS'!$B:$B,G$1,'BACKUP COUNTS'!$G:$G,G$2)) | H16: =IF(SUMIFS('BACKUP COUNTS'!$F:$F,'BACKUP COUNTS'!$A:$A,$A16,'BACKUP COUNTS'!$B:$B,H$1,'BACKUP COUNTS'!$G:$G,H$2)=0,"",SUMIFS('BACKUP COUNTS'!$F:$F,'BACKUP COUNTS'!$A:$A,$A16,'BACKUP COUNTS'!$B:$B,H$1,'BACKUP COUNTS'!$G:$G,H$2)) | I16: =IF(SUMIFS('BACKUP COUNTS'!$F:$F,'BACKUP COUNTS'!$A:$A,$A16,'BACKUP COUNTS'!$B:$B,I$1,'BACKUP COUNTS'!$G:$G,I$2)=0,"",SUMIFS('BACKUP COUNTS'!$F:$F,'BACKUP COUNTS'!$A:$A,$A16,'BACKUP COUNTS'!$B:$B,I$1,'BACKUP COUNTS'!$G:$G,I$2)) | J16: =IF(SUMIFS('BACKUP COUNTS'!$F:$F,'BACKUP COUNTS'!$A:$A,$A16,'BACKUP COUNTS'!$B:$B,J$1,'BACKUP COUNTS'!$G:$G,J$2)=0,"",SUMIFS('BACKUP COUNTS'!$F:$F,'BACKUP COUNTS'!$A:$A,$A16,'BACKUP COUNTS'!$B:$B,J$1,'BACKUP COUNTS'!$G:$G,J$2)) | K16: =IF(SUMIFS('BACKUP COUNTS'!$F:$F,'BACKUP COUNTS'!$A:$A,$A16,'BACKUP COUNTS'!$B:$B,K$1,'BACKUP COUNTS'!$G:$G,K$2)=0,"",SUMIFS('BACKUP COUNTS'!$F:$F,'BACKUP COUNTS'!$A:$A,$A16,'BACKUP COUNTS'!$B:$B,K$1,'BACKUP COUNTS'!$G:$G,K$2)) | ... R16: =IF(SUMIFS('BACKUP COUNTS'!$F:$F,'BACKUP COUNTS'!$A:$A,$A16,'BACKUP COUNTS'!$B:$B,R$1,'BACKUP COUNTS'!$G:$G,R$2)=0,"",SUMIFS('BACKUP COUNTS'!$F:$F,'BACKUP COUNTS'!$A:$A,$A16,'BACKUP COUNTS'!$B:$B,R$1,'BACKUP COUNTS'!$G:$G,R$2))
... A182: =IF(WEEKDAY(A181,2)=5,A181+3,A181+1) -> 46087 | C182: =IF(SUMIFS('BACKUP COUNTS'!$F:$F,'BACKUP COUNTS'!$A:$A,$A182,'BACKUP COUNTS'!$B:$B,C$2)=0,"",SUMIFS('BACKUP COUNTS'!$F:$F,'BACKUP COUNTS'!$A:$A,$A182,'BACKUP COUNTS'!$B:$B,C$2)) | D182: =IF(SUMIFS('BACKUP COUNTS'!$F:$F,'BACKUP COUNTS'!$A:$A,$A182,'BACKUP COUNTS'!$B:$B,D$1,'BACKUP COUNTS'!$G:$G,D$2)=0,"",SUMIFS('BACKUP COUNTS'!$F:$F,'BACKUP COUNTS'!$A:$A,$A182,'BACKUP COUNTS'!$B:$B,D$1,'BACKUP COUNTS'!$G:$G,D$2)) | E182: =IF(SUMIFS('BACKUP COUNTS'!$F:$F,'BACKUP COUNTS'!$A:$A,$A182,'BACKUP COUNTS'!$B:$B,E$1,'BACKUP COUNTS'!$G:$G,E$2)=0,"",SUMIFS('BACKUP COUNTS'!$F:$F,'BACKUP COUNTS'!$A:$A,$A182,'BACKUP COUNTS'!$B:$B,E$1,'BACKUP COUNTS'!$G:$G,E$2)) | F182: =IF(SUMIFS('BACKUP COUNTS'!$F:$F,'BACKUP COUNTS'!$A:$A,$A182,'BACKUP COUNTS'!$B:$B,F$1,'BACKUP COUNTS'!$G:$G,F$2)=0,"",SUMIFS('BACKUP COUNTS'!$F:$F,'BACKUP COUNTS'!$A:$A,$A182,'BACKUP COUNTS'!$B:$B,F$1,'BACKUP COUNTS'!$G:$G,F$2)) | G182: =IF(SUMIFS('BACKUP COUNTS'!$F:$F,'BACKUP COUNTS'!$A:$A,$A182,'BACKUP COUNTS'!$B:$B,G$1,'BACKUP COUNTS'!$G:$G,G$2)=0,"",SUMIFS('BACKUP COUNTS'!$F:$F,'BACKUP COUNTS'!$A:$A,$A182,'BACKUP COUNTS'!$B:$B,G$1,'BACKUP COUNTS'!$G:$G,G$2)) | H182: =IF(SUMIFS('BACKUP COUNTS'!$F:$F,'BACKUP COUNTS'!$A:$A,$A182,'BACKUP COUNTS'!$B:$B,H$1,'BACKUP COUNTS'!$G:$G,H$2)=0,"",SUMIFS('BACKUP COUNTS'!$F:$F,'BACKUP COUNTS'!$A:$A,$A182,'BACKUP COUNTS'!$B:$B,H$1,'BACKUP COUNTS'!$G:$G,H$2)) | I182: =IF(SUMIFS('BACKUP COUNTS'!$F:$F,'BACKUP COUNTS'!$A:$A,$A182,'BACKUP COUNTS'!$B:$B,I$1,'BACKUP COUNTS'!$G:$G,I$2)=0,"",SUMIFS('BACKUP COUNTS'!$F:$F,'BACKUP COUNTS'!$A:$A,$A182,'BACKUP COUNTS'!$B:$B,I$1,'BACKUP COUNTS'!$G:$G,I$2)) | J182: =IF(SUMIFS('BACKUP COUNTS'!$F:$F,'BACKUP COUNTS'!$A:$A,$A182,'BACKUP COUNTS'!$B:$B,J$1,'BACKUP COUNTS'!$G:$G,J$2)=0,"",SUMIFS('BACKUP COUNTS'!$F:$F,'BACKUP COUNTS'!$A:$A,$A182,'BACKUP COUNTS'!$B:$B,J$1,'BACKUP COUNTS'!$G:$G,J$2)) | K182: =IF(SUMIFS('BACKUP COUNTS'!$F:$F,'BACKUP COUNTS'!$A:$A,$A182,'BACKUP COUNTS'!$B:$B,K$1,'BACKUP COUNTS'!$G:$G,K$2)=0,"",SUMIFS('BACKUP COUNTS'!$F:$F,'BACKUP COUNTS'!$A:$A,$A182,'BACKUP COUNTS'!$B:$B,K$1,'BACKUP COUNTS'!$G:$G,K$2)) | ... R182: =IF(SUMIFS('BACKUP COUNTS'!$F:$F,'BACKUP COUNTS'!$A:$A,$A182,'BACKUP COUNTS'!$B:$B,R$1,'BACKUP COUNTS'!$G:$G,R$2)=0,"",SUMIFS('BACKUP COUNTS'!$F:$F,'BACKUP COUNTS'!$A:$A,$A182,'BACKUP COUNTS'!$B:$B,R$1,'BACKUP COUNTS'!$G:$G,R$2))
A183: =IF(WEEKDAY(A182,2)=5,A182+3,A182+1) -> 46090 | B183: Y | C183: =IF(SUMIFS('BACKUP COUNTS'!$F:$F,'BACKUP COUNTS'!$A:$A,$A183,'BACKUP COUNTS'!$B:$B,C$2)=0,"",SUMIFS('BACKUP COUNTS'!$F:$F,'BACKUP COUNTS'!$A:$A,$A183,'BACKUP COUNTS'!$B:$B,C$2)) | D183: =IF(SUMIFS('BACKUP COUNTS'!$F:$F,'BACKUP COUNTS'!$A:$A,$A183,'BACKUP COUNTS'!$B:$B,D$1,'BACKUP COUNTS'!$G:$G,D$2)=0,"",SUMIFS('BACKUP COUNTS'!$F:$F,'BACKUP COUNTS'!$A:$A,$A183,'BACKUP COUNTS'!$B:$B,D$1,'BACKUP COUNTS'!$G:$G,D$2)) | E183: =IF(SUMIFS('BACKUP COUNTS'!$F:$F,'BACKUP COUNTS'!$A:$A,$A183,'BACKUP COUNTS'!$B:$B,E$1,'BACKUP COUNTS'!$G:$G,E$2)=0,"",SUMIFS('BACKUP COUNTS'!$F:$F,'BACKUP COUNTS'!$A:$A,$A183,'BACKUP COUNTS'!$B:$B,E$1,'BACKUP COUNTS'!$G:$G,E$2)) | F183: =IF(SUMIFS('BACKUP COUNTS'!$F:$F,'BACKUP COUNTS'!$A:$A,$A183,'BACKUP COUNTS'!$B:$B,F$1,'BACKUP COUNTS'!$G:$G,F$2)=0,"",SUMIFS('BACKUP COUNTS'!$F:$F,'BACKUP COUNTS'!$A:$A,$A183,'BACKUP COUNTS'!$B:$B,F$1,'BACKUP COUNTS'!$G:$G,F$2)) | G183: =IF(SUMIFS('BACKUP COUNTS'!$F:$F,'BACKUP COUNTS'!$A:$A,$A183,'BACKUP COUNTS'!$B:$B,G$1,'BACKUP COUNTS'!$G:$G,G$2)=0,"",SUMIFS('BACKUP COUNTS'!$F:$F,'BACKUP COUNTS'!$A:$A,$A183,'BACKUP COUNTS'!$B:$B,G$1,'BACKUP COUNTS'!$G:$G,G$2)) | H183: =IF(SUMIFS('BACKUP COUNTS'!$F:$F,'BACKUP COUNTS'!$A:$A,$A183,'BACKUP COUNTS'!$B:$B,H$1,'BACKUP COUNTS'!$G:$G,H$2)=0,"",SUMIFS('BACKUP COUNTS'!$F:$F,'BACKUP COUNTS'!$A:$A,$A183,'BACKUP COUNTS'!$B:$B,H$1,'BACKUP COUNTS'!$G:$G,H$2)) | I183: =IF(SUMIFS('BACKUP COUNTS'!$F:$F,'BACKUP COUNTS'!$A:$A,$A183,'BACKUP COUNTS'!$B:$B,I$1,'BACKUP COUNTS'!$G:$G,I$2)=0,"",SUMIFS('BACKUP COUNTS'!$F:$F,'BACKUP COUNTS'!$A:$A,$A183,'BACKUP COUNTS'!$B:$B,I$1,'BACKUP COUNTS'!$G:$G,I$2)) | J183: =IF(SUMIFS('BACKUP COUNTS'!$F:$F,'BACKUP COUNTS'!$A:$A,$A183,'BACKUP COUNTS'!$B:$B,J$1,'BACKUP COUNTS'!$G:$G,J$2)=0,"",SUMIFS('BACKUP COUNTS'!$F:$F,'BACKUP COUNTS'!$A:$A,$A183,'BACKUP COUNTS'!$B:$B,J$1,'BACKUP COUNTS'!$G:$G,J$2)) | K183: =IF(SUMIFS('BACKUP COUNTS'!$F:$F,'BACKUP COUNTS'!$A:$A,$A183,'BACKUP COUNTS'!$B:$B,K$1,'BACKUP COUNTS'!$G:$G,K$2)=0,"",SUMIFS('BACKUP COUNTS'!$F:$F,'BACKUP COUNTS'!$A:$A,$A183,'BACKUP COUNTS'!$B:$B,K$1,'BACKUP COUNTS'!$G:$G,K$2)) | ... R183: =IF(SUMIFS('BACKUP COUNTS'!$F:$F,'BACKUP COUNTS'!$A:$A,$A183,'BACKUP COUNTS'!$B:$B,R$1,'BACKUP COUNTS'!$G:$G,R$2)=0,"",SUMIFS('BACKUP COUNTS'!$F:$F,'BACKUP COUNTS'!$A:$A,$A183,'BACKUP COUNTS'!$B:$B,R$1,'BACKUP COUNTS'!$G:$G,R$2))
A184: =IF(WEEKDAY(A183,2)=5,A183+3,A183+1) -> 46091 | B184: Y | C184: =IF(SUMIFS('BACKUP COUNTS'!$F:$F,'BACKUP COUNTS'!$A:$A,$A184,'BACKUP COUNTS'!$B:$B,C$2)=0,"",SUMIFS('BACKUP COUNTS'!$F:$F,'BACKUP COUNTS'!$A:$A,$A184,'BACKUP COUNTS'!$B:$B,C$2)) | D184: =IF(SUMIFS('BACKUP COUNTS'!$F:$F,'BACKUP COUNTS'!$A:$A,$A184,'BACKUP COUNTS'!$B:$B,D$1,'BACKUP COUNTS'!$G:$G,D$2)=0,"",SUMIFS('BACKUP COUNTS'!$F:$F,'BACKUP COUNTS'!$A:$A,$A184,'BACKUP COUNTS'!$B:$B,D$1,'BACKUP COUNTS'!$G:$G,D$2)) | E184: =IF(SUMIFS('BACKUP COUNTS'!$F:$F,'BACKUP COUNTS'!$A:$A,$A184,'BACKUP COUNTS'!$B:$B,E$1,'BACKUP COUNTS'!$G:$G,E$2)=0,"",SUMIFS('BACKUP COUNTS'!$F:$F,'BACKUP COUNTS'!$A:$A,$A184,'BACKUP COUNTS'!$B:$B,E$1,'BACKUP COUNTS'!$G:$G,E$2)) | F184: =IF(SUMIFS('BACKUP COUNTS'!$F:$F,'BACKUP COUNTS'!$A:$A,$A184,'BACKUP COUNTS'!$B:$B,F$1,'BACKUP COUNTS'!$G:$G,F$2)=0,"",SUMIFS('BACKUP COUNTS'!$F:$F,'BACKUP COUNTS'!$A:$A,$A184,'BACKUP COUNTS'!$B:$B,F$1,'BACKUP COUNTS'!$G:$G,F$2)) | G184: =IF(SUMIFS('BACKUP COUNTS'!$F:$F,'BACKUP COUNTS'!$A:$A,$A184,'BACKUP COUNTS'!$B:$B,G$1,'BACKUP COUNTS'!$G:$G,G$2)=0,"",SUMIFS('BACKUP COUNTS'!$F:$F,'BACKUP COUNTS'!$A:$A,$A184,'BACKUP COUNTS'!$B:$B,G$1,'BACKUP COUNTS'!$G:$G,G$2)) | H184: =IF(SUMIFS('BACKUP COUNTS'!$F:$F,'BACKUP COUNTS'!$A:$A,$A184,'BACKUP COUNTS'!$B:$B,H$1,'BACKUP COUNTS'!$G:$G,H$2)=0,"",SUMIFS('BACKUP COUNTS'!$F:$F,'BACKUP COUNTS'!$A:$A,$A184,'BACKUP COUNTS'!$B:$B,H$1,'BACKUP COUNTS'!$G:$G,H$2)) | I184: =IF(SUMIFS('BACKUP COUNTS'!$F:$F,'BACKUP COUNTS'!$A:$A,$A184,'BACKUP COUNTS'!$B:$B,I$1,'BACKUP COUNTS'!$G:$G,I$2)=0,"",SUMIFS('BACKUP COUNTS'!$F:$F,'BACKUP COUNTS'!$A:$A,$A184,'BACKUP COUNTS'!$B:$B,I$1,'BACKUP COUNTS'!$G:$G,I$2)) | J184: =IF(SUMIFS('BACKUP COUNTS'!$F:$F,'BACKUP COUNTS'!$A:$A,$A184,'BACKUP COUNTS'!$B:$B,J$1,'BACKUP COUNTS'!$G:$G,J$2)=0,"",SUMIFS('BACKUP COUNTS'!$F:$F,'BACKUP COUNTS'!$A:$A,$A184,'BACKUP COUNTS'!$B:$B,J$1,'BACKUP COUNTS'!$G:$G,J$2)) | K184: =IF(SUMIFS('BACKUP COUNTS'!$F:$F,'BACKUP COUNTS'!$A:$A,$A184,'BACKUP COUNTS'!$B:$B,K$1,'BACKUP COUNTS'!$G:$G,K$2)=0,"",SUMIFS('BACKUP COUNTS'!$F:$F,'BACKUP COUNTS'!$A:$A,$A184,'BACKUP COUNTS'!$B:$B,K$1,'BACKUP COUNTS'!$G:$G,K$2)) | ... R184: =IF(SUMIFS('BACKUP COUNTS'!$F:$F,'BACKUP COUNTS'!$A:$A,$A184,'BACKUP COUNTS'!$B:$B,R$1,'BACKUP COUNTS'!$G:$G,R$2)=0,"",SUMIFS('BACKUP COUNTS'!$F:$F,'BACKUP COUNTS'!$A:$A,$A184,'BACKUP COUNTS'!$B:$B,R$1,'BACKUP COUNTS'!$G:$G,R$2))
A185: =IF(WEEKDAY(A184,2)=5,A184+3,A184+1) -> 46092 | B185: Y | C185: =IF(SUMIFS('BACKUP COUNTS'!$F:$F,'BACKUP COUNTS'!$A:$A,$A185,'BACKUP COUNTS'!$B:$B,C$2)=0,"",SUMIFS('BACKUP COUNTS'!$F:$F,'BACKUP COUNTS'!$A:$A,$A185,'BACKUP COUNTS'!$B:$B,C$2)) | D185: =IF(SUMIFS('BACKUP COUNTS'!$F:$F,'BACKUP COUNTS'!$A:$A,$A185,'BACKUP COUNTS'!$B:$B,D$1,'BACKUP COUNTS'!$G:$G,D$2)=0,"",SUMIFS('BACKUP COUNTS'!$F:$F,'BACKUP COUNTS'!$A:$A,$A185,'BACKUP COUNTS'!$B:$B,D$1,'BACKUP COUNTS'!$G:$G,D$2)) | E185: =IF(SUMIFS('BACKUP COUNTS'!$F:$F,'BACKUP COUNTS'!$A:$A,$A185,'BACKUP COUNTS'!$B:$B,E$1,'BACKUP COUNTS'!$G:$G,E$2)=0,"",SUMIFS('BACKUP COUNTS'!$F:$F,'BACKUP COUNTS'!$A:$A,$A185,'BACKUP COUNTS'!$B:$B,E$1,'BACKUP COUNTS'!$G:$G,E$2)) | F185: =IF(SUMIFS('BACKUP COUNTS'!$F:$F,'BACKUP COUNTS'!$A:$A,$A185,'BACKUP COUNTS'!$B:$B,F$1,'BACKUP COUNTS'!$G:$G,F$2)=0,"",SUMIFS('BACKUP COUNTS'!$F:$F,'BACKUP COUNTS'!$A:$A,$A185,'BACKUP COUNTS'!$B:$B,F$1,'BACKUP COUNTS'!$G:$G,F$2)) | G185: =IF(SUMIFS('BACKUP COUNTS'!$F:$F,'BACKUP COUNTS'!$A:$A,$A185,'BACKUP COUNTS'!$B:$B,G$1,'BACKUP COUNTS'!$G:$G,G$2)=0,"",SUMIFS('BACKUP COUNTS'!$F:$F,'BACKUP COUNTS'!$A:$A,$A185,'BACKUP COUNTS'!$B:$B,G$1,'BACKUP COUNTS'!$G:$G,G$2)) | H185: =IF(SUMIFS('BACKUP COUNTS'!$F:$F,'BACKUP COUNTS'!$A:$A,$A185,'BACKUP COUNTS'!$B:$B,H$1,'BACKUP COUNTS'!$G:$G,H$2)=0,"",SUMIFS('BACKUP COUNTS'!$F:$F,'BACKUP COUNTS'!$A:$A,$A185,'BACKUP COUNTS'!$B:$B,H$1,'BACKUP COUNTS'!$G:$G,H$2)) | I185: =IF(SUMIFS('BACKUP COUNTS'!$F:$F,'BACKUP COUNTS'!$A:$A,$A185,'BACKUP COUNTS'!$B:$B,I$1,'BACKUP COUNTS'!$G:$G,I$2)=0,"",SUMIFS('BACKUP COUNTS'!$F:$F,'BACKUP COUNTS'!$A:$A,$A185,'BACKUP COUNTS'!$B:$B,I$1,'BACKUP COUNTS'!$G:$G,I$2)) | J185: =IF(SUMIFS('BACKUP COUNTS'!$F:$F,'BACKUP COUNTS'!$A:$A,$A185,'BACKUP COUNTS'!$B:$B,J$1,'BACKUP COUNTS'!$G:$G,J$2)=0,"",SUMIFS('BACKUP COUNTS'!$F:$F,'BACKUP COUNTS'!$A:$A,$A185,'BACKUP COUNTS'!$B:$B,J$1,'BACKUP COUNTS'!$G:$G,J$2)) | K185: =IF(SUMIFS('BACKUP COUNTS'!$F:$F,'BACKUP COUNTS'!$A:$A,$A185,'BACKUP COUNTS'!$B:$B,K$1,'BACKUP COUNTS'!$G:$G,K$2)=0,"",SUMIFS('BACKUP COUNTS'!$F:$F,'BACKUP COUNTS'!$A:$A,$A185,'BACKUP COUNTS'!$B:$B,K$1,'BACKUP COUNTS'!$G:$G,K$2)) | ... R185: =IF(SUMIFS('BACKUP COUNTS'!$F:$F,'BACKUP COUNTS'!$A:$A,$A185,'BACKUP COUNTS'!$B:$B,R$1,'BACKUP COUNTS'!$G:$G,R$2)=0,"",SUMIFS('BACKUP COUNTS'!$F:$F,'BACKUP COUNTS'!$A:$A,$A185,'BACKUP COUNTS'!$B:$B,R$1,'BACKUP COUNTS'!$G:$G,R$2))
A186: =IF(WEEKDAY(A185,2)=5,A185+3,A185+1) -> 46093 | B186: Y | C186: =IF(SUMIFS('BACKUP COUNTS'!$F:$F,'BACKUP COUNTS'!$A:$A,$A186,'BACKUP COUNTS'!$B:$B,C$2)=0,"",SUMIFS('BACKUP COUNTS'!$F:$F,'BACKUP COUNTS'!$A:$A,$A186,'BACKUP COUNTS'!$B:$B,C$2)) | D186: =IF(SUMIFS('BACKUP COUNTS'!$F:$F,'BACKUP COUNTS'!$A:$A,$A186,'BACKUP COUNTS'!$B:$B,D$1,'BACKUP COUNTS'!$G:$G,D$2)=0,"",SUMIFS('BACKUP COUNTS'!$F:$F,'BACKUP COUNTS'!$A:$A,$A186,'BACKUP COUNTS'!$B:$B,D$1,'BACKUP COUNTS'!$G:$G,D$2)) | E186: =IF(SUMIFS('BACKUP COUNTS'!$F:$F,'BACKUP COUNTS'!$A:$A,$A186,'BACKUP COUNTS'!$B:$B,E$1,'BACKUP COUNTS'!$G:$G,E$2)=0,"",SUMIFS('BACKUP COUNTS'!$F:$F,'BACKUP COUNTS'!$A:$A,$A186,'BACKUP COUNTS'!$B:$B,E$1,'BACKUP COUNTS'!$G:$G,E$2)) | F186: =IF(SUMIFS('BACKUP COUNTS'!$F:$F,'BACKUP COUNTS'!$A:$A,$A186,'BACKUP COUNTS'!$B:$B,F$1,'BACKUP COUNTS'!$G:$G,F$2)=0,"",SUMIFS('BACKUP COUNTS'!$F:$F,'BACKUP COUNTS'!$A:$A,$A186,'BACKUP COUNTS'!$B:$B,F$1,'BACKUP COUNTS'!$G:$G,F$2)) | G186: =IF(SUMIFS('BACKUP COUNTS'!$F:$F,'BACKUP COUNTS'!$A:$A,$A186,'BACKUP COUNTS'!$B:$B,G$1,'BACKUP COUNTS'!$G:$G,G$2)=0,"",SUMIFS('BACKUP COUNTS'!$F:$F,'BACKUP COUNTS'!$A:$A,$A186,'BACKUP COUNTS'!$B:$B,G$1,'BACKUP COUNTS'!$G:$G,G$2)) | H186: =IF(SUMIFS('BACKUP COUNTS'!$F:$F,'BACKUP COUNTS'!$A:$A,$A186,'BACKUP COUNTS'!$B:$B,H$1,'BACKUP COUNTS'!$G:$G,H$2)=0,"",SUMIFS('BACKUP COUNTS'!$F:$F,'BACKUP COUNTS'!$A:$A,$A186,'BACKUP COUNTS'!$B:$B,H$1,'BACKUP COUNTS'!$G:$G,H$2)) | I186: =IF(SUMIFS('BACKUP COUNTS'!$F:$F,'BACKUP COUNTS'!$A:$A,$A186,'BACKUP COUNTS'!$B:$B,I$1,'BACKUP COUNTS'!$G:$G,I$2)=0,"",SUMIFS('BACKUP COUNTS'!$F:$F,'BACKUP COUNTS'!$A:$A,$A186,'BACKUP COUNTS'!$B:$B,I$1,'BACKUP COUNTS'!$G:$G,I$2)) | J186: =IF(SUMIFS('BACKUP COUNTS'!$F:$F,'BACKUP COUNTS'!$A:$A,$A186,'BACKUP COUNTS'!$B:$B,J$1,'BACKUP COUNTS'!$G:$G,J$2)=0,"",SUMIFS('BACKUP COUNTS'!$F:$F,'BACKUP COUNTS'!$A:$A,$A186,'BACKUP COUNTS'!$B:$B,J$1,'BACKUP COUNTS'!$G:$G,J$2)) | K186: =IF(SUMIFS('BACKUP COUNTS'!$F:$F,'BACKUP COUNTS'!$A:$A,$A186,'BACKUP COUNTS'!$B:$B,K$1,'BACKUP COUNTS'!$G:$G,K$2)=0,"",SUMIFS('BACKUP COUNTS'!$F:$F,'BACKUP COUNTS'!$A:$A,$A186,'BACKUP COUNTS'!$B:$B,K$1,'BACKUP COUNTS'!$G:$G,K$2)) | ... R186: =IF(SUMIFS('BACKUP COUNTS'!$F:$F,'BACKUP COUNTS'!$A:$A,$A186,'BACKUP COUNTS'!$B:$B,R$1,'BACKUP COUNTS'!$G:$G,R$2)=0,"",SUMIFS('BACKUP COUNTS'!$F:$F,'BACKUP COUNTS'!$A:$A,$A186,'BACKUP COUNTS'!$B:$B,R$1,'BACKUP COUNTS'!$G:$G,R$2))
A187: =IF(WEEKDAY(A186,2)=5,A186+3,A186+1) -> 46094 | B187: Y | C187: =IF(SUMIFS('BACKUP COUNTS'!$F:$F,'BACKUP COUNTS'!$A:$A,$A187,'BACKUP COUNTS'!$B:$B,C$2)=0,"",SUMIFS('BACKUP COUNTS'!$F:$F,'BACKUP COUNTS'!$A:$A,$A187,'BACKUP COUNTS'!$B:$B,C$2)) | D187: =IF(SUMIFS('BACKUP COUNTS'!$F:$F,'BACKUP COUNTS'!$A:$A,$A187,'BACKUP COUNTS'!$B:$B,D$1,'BACKUP COUNTS'!$G:$G,D$2)=0,"",SUMIFS('BACKUP COUNTS'!$F:$F,'BACKUP COUNTS'!$A:$A,$A187,'BACKUP COUNTS'!$B:$B,D$1,'BACKUP COUNTS'!$G:$G,D$2)) | E187: =IF(SUMIFS('BACKUP COUNTS'!$F:$F,'BACKUP COUNTS'!$A:$A,$A187,'BACKUP COUNTS'!$B:$B,E$1,'BACKUP COUNTS'!$G:$G,E$2)=0,"",SUMIFS('BACKUP COUNTS'!$F:$F,'BACKUP COUNTS'!$A:$A,$A187,'BACKUP COUNTS'!$B:$B,E$1,'BACKUP COUNTS'!$G:$G,E$2)) | F187: =IF(SUMIFS('BACKUP COUNTS'!$F:$F,'BACKUP COUNTS'!$A:$A,$A187,'BACKUP COUNTS'!$B:$B,F$1,'BACKUP COUNTS'!$G:$G,F$2)=0,"",SUMIFS('BACKUP COUNTS'!$F:$F,'BACKUP COUNTS'!$A:$A,$A187,'BACKUP COUNTS'!$B:$B,F$1,'BACKUP COUNTS'!$G:$G,F$2)) | G187: =IF(SUMIFS('BACKUP COUNTS'!$F:$F,'BACKUP COUNTS'!$A:$A,$A187,'BACKUP COUNTS'!$B:$B,G$1,'BACKUP COUNTS'!$G:$G,G$2)=0,"",SUMIFS('BACKUP COUNTS'!$F:$F,'BACKUP COUNTS'!$A:$A,$A187,'BACKUP COUNTS'!$B:$B,G$1,'BACKUP COUNTS'!$G:$G,G$2)) | H187: =IF(SUMIFS('BACKUP COUNTS'!$F:$F,'BACKUP COUNTS'!$A:$A,$A187,'BACKUP COUNTS'!$B:$B,H$1,'BACKUP COUNTS'!$G:$G,H$2)=0,"",SUMIFS('BACKUP COUNTS'!$F:$F,'BACKUP COUNTS'!$A:$A,$A187,'BACKUP COUNTS'!$B:$B,H$1,'BACKUP COUNTS'!$G:$G,H$2)) | I187: =IF(SUMIFS('BACKUP COUNTS'!$F:$F,'BACKUP COUNTS'!$A:$A,$A187,'BACKUP COUNTS'!$B:$B,I$1,'BACKUP COUNTS'!$G:$G,I$2)=0,"",SUMIFS('BACKUP COUNTS'!$F:$F,'BACKUP COUNTS'!$A:$A,$A187,'BACKUP COUNTS'!$B:$B,I$1,'BACKUP COUNTS'!$G:$G,I$2)) | J187: =IF(SUMIFS('BACKUP COUNTS'!$F:$F,'BACKUP COUNTS'!$A:$A,$A187,'BACKUP COUNTS'!$B:$B,J$1,'BACKUP COUNTS'!$G:$G,J$2)=0,"",SUMIFS('BACKUP COUNTS'!$F:$F,'BACKUP COUNTS'!$A:$A,$A187,'BACKUP COUNTS'!$B:$B,J$1,'BACKUP COUNTS'!$G:$G,J$2)) | K187: =IF(SUMIFS('BACKUP COUNTS'!$F:$F,'BACKUP COUNTS'!$A:$A,$A187,'BACKUP COUNTS'!$B:$B,K$1,'BACKUP COUNTS'!$G:$G,K$2)=0,"",SUMIFS('BACKUP COUNTS'!$F:$F,'BACKUP COUNTS'!$A:$A,$A187,'BACKUP COUNTS'!$B:$B,K$1,'BACKUP COUNTS'!$G:$G,K$2)) | ... R187: =IF(SUMIFS('BACKUP COUNTS'!$F:$F,'BACKUP COUNTS'!$A:$A,$A187,'BACKUP COUNTS'!$B:$B,R$1,'BACKUP COUNTS'!$G:$G,R$2)=0,"",SUMIFS('BACKUP COUNTS'!$F:$F,'BACKUP COUNTS'!$A:$A,$A187,'BACKUP COUNTS'!$B:$B,R$1,'BACKUP COUNTS'!$G:$G,R$2))
